Workbook

Sheet P ROFIQ (W8515DT)
B1: TANGGAL | C1: NO. POL | D1: DRIVER | E1: MERK KEDELAI | F1: PENERIMA | G1: BERAT (kg) | H1: ONGKOSAN | J1: SAKU SOPIR | L1: SETORAN | M1: KERUSAKAN
B2: 45078 | C2: B 9705 FYV | D2: PAK YOYOK | E2: PANAH | F2: PAK JAMIL | G2: 9000 | H2: 1400000 | J2: 900000 | L2: =H2-J2 -> 500000 | M2: 450000
B3: 45080 | C3: B 9705 FYV | D3: PAK YOYOK | E3: PANAH | F3: BU YATINI | G3: 9000 | H3: 1400000 | J3: 900000 | L3: =H3-J3 -> 500000
B4: 45082 | C4: B 9705 FYV | D4: PAK YOYOK | E4: PANAH | F4: PAK JAMIL | G4: 9000 | H4: 1400000 | J4: 900000 | L4: =H4-J4 -> 500000
B5: 45083 | C5: B 9705 FYV | D5: PAK YOYOK | E5: LOTUS | F5: PAK SLAMET TOBO | G5: 9000 | H5: 1215000 | J5: 700000 | L5: =H5-J5 -> 515000
B6: 45084 | C6: B 9705 FYV | D6: PAK YOYOK | E6: PANAH | F6: PAK JAMIL | G6: 9000 | H6: 1400000 | J6: 900000 | L6: =H6-J6 -> 500000
B7: 45085 | C7: B 9705 FYV | D7: PAK YOYOK | E7: PANAH | F7: MAS ARIK | G7: 9000 | H7: 1400000 | J7: 900000 | L7: =H7-J7 -> 500000
B8: 45086 | C8: B 9705 FYV | D8: PAK YOYOK | E8: LOTUS | F8: ABAH PRANOTO BLITAR | G8: 8500 | H8: 1300000 | J8: 850000 | L8: =H8-J8 -> 450000
B9: 45090 | C9: B 9705 FYV | D9: PAK YOYOK | E9: PANAH | F9: BU KASMI MADIUN | G9: 9000 | H9: 1350000 | J9: 800000 | L9: =H9-J9 -> 550000 | M9: 1727000
B10: 45091 | C10: B 9705 FYV | D10: PAK YOYOK | E10: LOTUS | F10: PAK SAIKU | G10: 8500 | H10: 1230000 | J10: 700000 | L10: =H10-J10 -> 530000
B11: 45092 | C11: B 9705 FYV | D11: PAK YOYOK | E11: PANAH | F11: PAK JAMIL | G11: 9000 | H11: 1400000 | J11: 900000 | L11: =H11-J11 -> 500000
B12: 45093 | C12: B 9705 FYV | D12: PAK YOYOK | E12: PANAH | F12: PAK JAMIL | G12: 9000 | H12: 1400000 | J12: 900000 | L12: =H12-J12 -> 500000
B13: 45094 | C13: B 9705 FYV | D13: PAK YOYOK | E13: PANAH | F13: PAK JAMIL | G13: 9000 | H13: 1400000 | J13: 900000 | L13: =H13-J13 -> 500000
B14: 45096 | C14: B 9705 FYV | D14: PAK YOYOK | E14: LOTUS | F14: PAK RAMIN | H14: 1450000 | J14: 900000 | L14: =H14-J14 -> 550000 | M14: 63000
B15: 45097 | C15: B 9705 FYV | D15: PAK YOYOK | E15: PANAH | F15: KOPTI WAHYU SATRIA MALANG | H15: 1200000 | J15: 640000 | L15: =H15-J15 -> 560000
B16: 45098 | C16: B 9705 FYV | D16: PAK YOYOK | E16: PANAH | F16: PAK JAMIL | G16: 8500 | H16: 1400000 | J16: 900000 | L16: =H16-J16 -> 500000
B17: 45099 | C17: B 9705 FYV | D17: PAK YOYOK | E17: LOTUS | F17: MAS ARIK | H17: 1400000 | J17: 900000 | L17: =H17-J17 -> 500000
B18: 45100 | C18: B 9705 FYV | D18: PAK YOYOK | E18: PANAH | F18: PAK JAMIL | H18: 1400000
B19: 45101 | C19: B 9705 FYV | D19: PAK YOYOK | E19: PANAH | F19: PAK RAMIN | H19: 1450000 | J19: 900000 | L19: =H19-J19 -> 550000 | M19: 3870000
B20: 45104 | C20: B 9705 FYV | D20: PAK YOYOK | E20: PANAH | F20: BU KASMI MADIUN | H20: 1350000 | J20: 800000 | L20: =H20-J20 -> 550000
B21: 45105 | C21: B 9705 FYV | D21: PAK YOYOK | E21: LOTUS | F21: TOKO | H21: 675000 | J21: 350000 | L21: =H21-J21 -> 325000 | M21: 670000
L22: =SUM(L1:L21) -> 9580000 | M22: =SUM(M1:M21) -> 6780000
L23: =L22-M22 -> 2800000
B25: TANGGAL | C25: NO. POL | D25: DRIVER | E25: MERK KEDELAI | F25: PENERIMA | G25: BERAT (kg) | H25: ONGKOSAN | J25: SAKU SOPIR | L25: SETORAN | M25: KERUSAKAN
B26: 45113 | C26: B 9705 FYV | D26: Pak Yoyok | E26: Panah Biru | F26: Kopti Wahyu Satria Malang | G26: 8500 | H26: 1100000 | J26: 640000 | L26: =H26-J26 -> 460000
B27: 45114 | C27: B 9705 FYV | D27: Pak Yoyok | E27: Panah Biru | F27: Pak Iwan Bojonegoro Kota | G27: 9000 | H27: 1350000 | J27: 800000 | L27: =H27-J27 -> 550000 | M27: 120000
B28: 45115 | C28: B 9705 FYV | D28: Pak Yoyok | E28: Lotus | G28: 9000 | H28: 1080000 | J28: 640000 | L28: =H28-J28 -> 440000 | M28: 60000
B29: 45117 | C29: B 9705 FYV | D29: Pak Yoyok | E29: Lotus | F29: Pak saiku malang | G29: 8500 | H29: 1230000 | J29: 700000 | L29: =H29-J29 -> 530000 | M29: 184000
B30: 45118 | C30: B 9705 FYV | D30: Pak Yoyok | E30: Lotus | F30: Toko bumi berkah | G30: 9000 | H30: 675000 | J30: 350000 | L30: =H30-J30 -> 325000 | M30: 993000
B31: 45119 | C31: B 9705 FYV | D31: Pak Yoyok | E31: Lotus | F31: Pak ramin | G31: 9000 | H31: 1450000 | J31: 900000 | L31: =H31-J31 -> 550000
B32: 45120 | C32: B 9705 FYV | D32: Pak Yoyok | E32: Lotus | F32: Pak ramin | G32: 9000 | H32: 1450000 | J32: 900000 | L32: =H32-J32 -> 550000 | M32: 580000
B33: 45121 | C33: B 9705 FYV | D33: Pak Yoyok | E33: Lotus | F33: Abah slamet | G33: 9000 | H33: 1215000 | J33: 700000 | L33: =H33-J33 -> 515000
B34: 45122 | C34: B 9705 FYV | D34: Pak Yoyok | E34: Lotus | F34: Pak Iwan Bojonegoro Kota | G34: 9000 | H34: 1080000 | J34: 640000 | L34: =H34-J34 -> 440000 | M34: 275000
B35: 45124 | C35: B 9705 FYV | D35: Pak Yoyok | E35: Lotus | F35: Kopti Wahyu Satria Malang | G35: 8500 | H35: 1100000 | J35: 640000 | L35: =H35-J35 -> 460000 | M35: 626000
B36: 45125 | C36: B 9705 FYV | D36: Pak Yoyok | E36: Lotus | F36: Abah slamet | G36: 9000 | H36: 1215000 | J36: 700000 | L36: =H36-J36 -> 515000
B37: 45127 | C37: B 9705 FYV | D37: Pak Yoyok | E37: Lotus | F37: Pak ramin | G37: 9000 | H37: 1450000 | J37: 900000 | L37: =H37-J37 -> 550000
B38: 45128 | C38: B 9705 FYV | D38: Pak Yoyok | E38: Lotus | F38: Pak ramin | G38: 9000 | H38: 1450000 | J38: 900000 | L38: =H38-J38 -> 550000
B39: 45129 | C39: B 9705 FYV | D39: Pak Yoyok | E39: Lotus | F39: Toko bumi berkah | G39: 9000 | H39: 675000 | J39: 350000 | L39: =H39-J39 -> 325000 | M39: 110000
B40: 45131 | C40: B 9705 FYV | D40: Pak Yoyok | E40: Lotus | F40: Pak arik ngawi | G40: 9000 | H40: 1400000 | J40: 900000 | L40: =H40-J40 -> 500000 | M40: 325000
B41: 45132 | C41: B 9705 FYV | D41: Pak Yoyok | E41: Lotus | F41: Bu Kasmi Madiun | G41: 9000 | H41: 1350000 | J41: 800000 | L41: =H41-J41 -> 550000
...

Sheet P IRVAN (W9366PA)
B1: TANGGAL | C1: NO. POL | D1: DRIVER | E1: MERK KEDELAI | F1: PENERIMA | G1: BERAT (kg) | H1: ONGKOSAN | J1: SAKU SOPIR | L1: SETORAN | M1: KERUSAKAN
B2: 45079 | C2: S 9013 UJ | D2: DIKI | E2: HIU | F2: BU KASMI MADIUN | G2: 9000 | H2: 1350000 | J2: 800000 | L2: =H2-J2 -> 550000 | M2: 357500
B3: 45080 | C3: S 9013 UJ | D3: DIKI | E3: JEMPOL SIP | F3: PAK SLAMET TOBO | G3: 9000 | H3: 1215000 | J3: 700000 | L3: =H3-J3 -> 515000
B4: 45082 | C4: S 9013 UJ | D4: DIKI | E4: JEMPOL SIP | F4: PAK RAMIN NGAWI | G4: 9000 | H4: 1450000 | J4: 900000 | L4: =H4-J4 -> 550000
B5: 45084 | C5: S 9013 UJ | D5: DIKI | E5: LOTUS | F5: PAK RAMIN NGAWI | G5: 9000 | H5: 1450000 | J5: 900000 | L5: =H5-J5 -> 550000 | M5: 109000
B6: 45085 | C6: S 9013 UJ | D6: DIKI | E6: LOTUS | F6: PAK SLAMET TOBO | G6: 9000 | H6: 1215000 | J6: 700000 | L6: =H6-J6 -> 515000 | M6: 1425000
B7: 45086 | C7: S 9013 UJ | D7: DIKI | E7: JEMPOL SIP | F7: ABAH KOHAR | G7: 9000 | H7: 975000 | J7: 500000 | L7: =H7-J7 -> 475000
B8: 45087 | C8: S 9013 UJ | D8: DIKI | E8: HIU | F8: BU KASMI MADIUN | G8: 9000 | H8: 1350000 | J8: 800000 | L8: =H8-J8 -> 550000
B9: 45089 | C9: S 9013 UJ | D9: DIKI | E9: PANAH | F9: PAK JAMIL NGAWI | G9: 9000 | H9: 1400000 | J9: 900000 | L9: =H9-J9 -> 500000 | M9: 353000
B10: 45090 | C10: S 9013 UJ | D10: DIKI | E10: LOTUS | F10: PAK RAMIN NGAWI | G10: 9000 | H10: 1450000 | J10: 900000 | L10: =H10-J10 -> 550000 | M10: 635000
B11: 45091 | C11: S 9013 UJ | D11: DIKI | E11: PANAH | F11: PAK RAMIN NGAWI | G11: 9000 | H11: 1450000 | J11: 900000 | L11: =H11-J11 -> 550000
B12: 45092 | C12: S 9013 UJ | D12: DIKI | E12: PANAH | F12: BU KASMI MADIUN | G12: 9000 | H12: 1350000 | J12: 800000 | L12: =H12-J12 -> 550000
B13: 45094 | C13: S 9013 UJ | D13: DIKI | E13: PANAH | F13: ABAH PRANOTO | G13: 8500 | H13: 1300000 | J13: 850000 | L13: =H13-J13 -> 450000
B14: 45096 | C14: S 9013 UJ | D14: DIKI | E14: LOTUS | F14: PAK RAMIN NGAWI | G14: 9000 | H14: 1450000 | J14: 900000 | L14: =H14-J14 -> 550000 | M14: 415000
B15: 45097 | C15: S 9013 UJ | D15: DIKI | E15: PANAH | F15: MAS ARIK | G15: 9000 | H15: 1400000 | J15: 900000 | L15: =H15-J15 -> 500000
B16: 45097 | C16: S 9013 UJ | D16: DIKI | E16: LOTUS | F16: KOPTI GIRI GRESIK | G16: 9000 | H16: 720000 | J16: 350000 | L16: =H16-J16 -> 370000
B17: 45098 | C17: S 9013 UJ | D17: DIKI | E17: PANAH | F17: BU KASMI MADIUN | G17: 9000 | H17: 1350000 | J17: 800000 | L17: =H17-J17 -> 550000
B18: 45099 | C18: S 9013 UJ | D18: DIKI | E18: PANAH | F18: PAK JAMIL NGAWI | G18: 9000 | H18: 1400000 | J18: 900000 | L18: =H18-J18 -> 500000 | M18: 3176000
B19: 45100 | C19: S 9013 UJ | D19: DIKI | E19: LOTUS | F19: PAK RAMIN NGAWI | G19: 9000 | H19: 1450000 | J19: 900000 | L19: =H19-J19 -> 550000 | M19: 150000
B20: 45104 | C20: S 9013 UJ | D20: DIKI | E20: LOTUS | F20: PAK SLAMET TOBO | G20: 9000 | H20: 1215000 | J20: 700000 | L20: =H20-J20 -> 515000 | M20: 1407000
B21: 45105 | C21: S 9013 UJ | D21: DIKI | E21: PANAH | F21: BU YATINI | G21: 9000 | H21: 1400000 | J21: 900000 | L21: =H21-J21 -> 500000
L22: =SUM(L1:L20) -> 9840000 | M22: =SUM(M1:M20) -> 8027500
L23: =L22-M22 -> 1812500
B25: TANGGAL | C25: NO. POL | D25: DRIVER | E25: MERK KEDELAI | F25: PENERIMA | G25: BERAT (kg) | H25: ONGKOSAN | J25: SAKU SOPIR | L25: SETORAN | M25: KERUSAKAN
B26: 45111 | C26: S 9013 UJ | D26: Mas Diky | E26: Lotus | F26: Kopti Wahyu Satria Malang | G26: 8500 | H26: 1100000 | J26: 640000 | L26: =H26-J26 -> 460000
B27: 45112 | C27: S 9013 UJ | D27: Mas Diky | E27: Lotus | F27: Pak Herwanto Jombang Sumobito | G27: 9000 | H27: 810000 | J27: 500000 | L27: =H27-J27 -> 310000
B28: 45113 | L28: =H28-J28 -> 0 | M28: 1319000
B29: 45114 | L29: =H29-J29 -> 0 | M29: 12700000
B30: 45115 | C30: S 9013 UJ | D30: Mas Diky | E30: Hiu | F30: Mbak Nur Kopti Mojokerto | G30: 9000 | H30: 765000 | J30: 450000 | L30: =H30-J30 -> 315000
B31: 45118 | C31: S 9013 UJ | D31: Mas Diky | E31: Panah biru | F31: Abah kohar bojonegoro | G31: 9000 | H31: 975000 | J31: 500000 | L31: =H31-J31 -> 475000 | M31: 1550000
B32: 45119 | C32: S 9013 UJ | D32: Mas Diky | E32: Panah biru | F32: bu kasmi madiun | G32: 9000 | H32: 1350000 | J32: 800000 | L32: =H32-J32 -> 550000
B33: 45120 | C33: S 9013 UJ | D33: Mas Diky | E33: Panah biru | F33: Pak jamil | G33: 9000 | H33: 1400000 | J33: 900000 | L33: =H33-J33 -> 500000
B34: 45121 | C34: S 9013 UJ | D34: Mas Diky | E34: Hiu | F34: bu kasmi madiun | G34: 9000 | H34: 1350000 | J34: 800000 | L34: =H34-J34 -> 550000
B35: 45122 | C35: S 9013 UJ | D35: Mas Diky | E35: Lotus | F35: Bu iin sepanjang | G35: 9000 | H35: 675000 | J35: 375000 | L35: =H35-J35 -> 300000
B36: 45127 | C36: S 9013 UJ | D36: Mas Diky | E36: Hiu | F36: bu kasmi madiun | G36: 9000 | H36: 1350000 | J36: 800000 | L36: =H36-J36 -> 550000
B37: 45128 | C37: S 9013 UJ | D37: Mas Diky | E37: Lotus | F37: Pak slamet | G37: 9000 | H37: 1215000 | J37: 700000 | L37: =H37-J37 -> 515000
B38: 45129 | C38: S 9013 UJ | D38: Mas Diky | E38: Lotus | F38: Pak slamet | G38: 9000 | H38: 1215000 | J38: 700000 | L38: =H38-J38 -> 515000 | M38: 981000
B39: 45131 | C39: S 9013 UJ | D39: Mas Diky | E39: Lotus | F39: Bu prapti nganjuk | G39: 9000 | H39: 1200000 | J39: 640000 | L39: =H39-J39 -> 560000
B40: 45132 | C40: S 9013 UJ | D40: Mas Diky | E40: Panah biru | F40: bu kasmi madiun | G40: 9000 | H40: 1350000 | J40: 800000 | L40: =H40-J40 -> 550000
B41: 45133 | C41: S 9013 UJ | D41: Mas Diky | L41: =H41-J41 -> 0 | M41: 387000
...

Sheet P ZAENAL (P9611GA)
B1: TANGGAL | C1: NO. POL | D1: DRIVER | E1: MERK KEDELAI | F1: PENERIMA | G1: BERAT (kg) | H1: ONGKOSAN | I1: KET | J1: SAKU SOPIR | K1: KET | L1: SETORAN | M1: KERUSAKAN
B2: 45555 | M2: 261000
B3: 45556 | C3: W 8882 DS | D3: Pak Rofiq | E3: Hiu | F3: Toko putra bumi berkah | G3: 9000 | H3: 675000 | I3: Cash | J3: 350000 | K3: Cash | L3: =H3-J3 -> 325000
B4: 45556 | C4: W 8882 DS | D4: Pak Rofiq | E4: Lotus | F4: Pak ramin ngawi | G4: 9000 | H4: 1440000 | I4: TF | J4: 900000 | K4: Cash | L4: =H4-J4 -> 540000 | M4: 150000
B5: 45558 | C5: W 8882 DS | D5: Pak Rofiq | E5: Hiu | F5: Bu kasmi madiun | G5: 10000 | H5: 1500000 | I5: TF | J5: 850000 | K5: Cash | L5: =H5-J5 -> 650000
B6: 45559 | C6: W 8882 DS | D6: Pak Rofiq | M6: 3259000
B7: 45561 | C7: W 8882 DS | D7: Pak Rofiq | E7: Pakan Ternak | F7: Jember | G7: 8000 | H7: 1500000 | I7: TF | J7: 900000 | K7: Cash | L7: =H7-J7 -> 600000 | M7: 200000
B8: 45562 | C8: W 8882 DS | D8: Pak Rofiq | E8: Panah | F8: Umik Nardi Malang | G8: 10000 | H8: 1500000 | I8: TF | J8: 750000 | K8: TF | L8: =H8-J8 -> 750000
B9: 45563 | C9: W 8882 DS | D9: Pak Rofiq | E9: Panah | F9: Bu kasmi madiun | G9: 10000 | H9: 1500000 | I9: TF | J9: 850000 | K9: TF | L9: =H9-J9 -> 650000
B10: 45565 | C10: W 8882 DS | D10: Pak Rofiq | E10: Lotus | F10: Mba Nur Mojokerto | G10: 9000 | H10: 765000 | I10: TF | J10: 450000 | K10: Cash | L10: =H10-J10 -> 315000
L11: =SUM(L3:L10) -> 3830000 | M11: =SUM(M2:M10) -> 3870000
L12: =L11-M11 -> -40000
B17: TANGGAL | C17: NO. POL | D17: DRIVER | E17: MERK KEDELAI | F17: PENERIMA | G17: BERAT (kg) | H17: ONGKOSAN | I17: KET | J17: SAKU SOPIR | K17: KET | L17: SETORAN | M17: KERUSAKAN
B18: 45566 | C18: W 8882 DS | D18: Pak Rofiq | E18: Lotus | F18: Abah slamet Bojonegoro | G18: 9000 | H18: 1215000 | I18: Cash | J18: 700000 | K18: Cash | L18: =H18-J18 -> 515000
B19: 45567 | C19: W 8882 DS | D19: Pak Rofiq | E19: Tulip | F19: Roni Toko Sederhana Malang | G19: 8500 | H19: 1200000 | I19: Cash | J19: 640000 | K19: Cash | L19: =H19-J19 -> 560000
B20: 45568 | C20: W 8882 DS | D20: Pak Rofiq | E20: Panah | F20: Pak Anwar Porong | G20: 8000 | H20: 800000 | I20: Cash | J20: 400000 | K20: Cash | L20: =H20-J20 -> 400000
B21: 45568 | C21: W 8882 DS | D21: Pak Rofiq | E21: Hiu | F21: Bu qusaimah pare | G21: 9000 | H21: 1100000 | I21: Cash | J21: 650000 | K21: Cash | L21: =H21-J21 -> 450000
B22: 45569 | C22: W 8882 DS | D22: Pak Rofiq | E22: Lotus | F22: Pak Yudi Bojonegoro | G22: 9000 | H22: 900000 | I22: Cash | J22: 500000 | K22: Cash | L22: =H22-J22 -> 400000
B23: 45570 | C23: W 8882 DS | D23: Pak Rofiq | E23: Panah | F23: Bu Tutik Bojonegoro | G23: 9000 | H23: 1125000 | I23: Cash | J23: 640000 | K23: Cash | L23: =H23-J23 -> 485000 | M23: 1400000
B24: 45574 | C24: W 8882 DS | D24: Pak Rofiq | E24: Tulip | F24: Roni Toko Sederhana Malang | G24: 8500 | H24: 1200000 | I24: Cash | J24: 640000 | K24: Cash | L24: =H24-J24 -> 560000 | M24: 325000
B25: 45575 | C25: W 8882 DS | D25: Pak Rofiq | E25: Panah | F25: BU Kasmi Madiun | G25: 10000 | H25: 1500000 | I25: TF | J25: 850000 | K25: Cash | L25: =H25-J25 -> 650000
B26: 45576 | C26: W 8882 DS | D26: Pak Rofiq | E26: Hiu | F26: Pak Yanto Porong | G26: 9000 | H26: 810000 | I26: TF | J26: 450000 | K26: TF | L26: =H26-J26 -> 360000
B27: 45577 | C27: W 8882 DS | D27: Pak Rofiq | E27: Panah | F27: Pak Rudi Sidoarjo | G27: 9000 | H27: 720000 | I27: Cash | J27: 400000 | K27: Cash | L27: =H27-J27 -> 320000
B28: 45581 | C28: W 8882 DS | D28: Pak Rofiq | E28: Lotus | F28: Pak ramin ngawi | G28: 10000 | H28: 1600000 | I28: TF | J28: 975000 | K28: Cash | L28: =H28-J28 -> 625000
B29: 45582 | C29: W 8882 DS | D29: Pak Rofiq | E29: Hiu | F29: Bu Kasmi Madiun | G29: 10000 | H29: 1500000 | I29: TF | J29: 850000 | K29: TF | L29: =H29-J29 -> 650000
B30: 45584 | C30: W 8882 DS | D30: Pak Rofiq | E30: Hiu | F30: Bu Kasmi Madiun | G30: 10000 | H30: 1500000 | I30: TF | J30: 850000 | K30: Cash | L30: =H30-J30 -> 650000
B31: 45586 | C31: W 8882 DS | D31: Pak Rofiq | E31: Tulip | F31: Roni Toko Sederhana Malang | G31: 8500 | H31: 1200000 | I31: Cash | J31: 640000 | K31: Cash | L31: =H31-J31 -> 560000
B32: 45587 | C32: W 8882 DS | D32: Pak Rofiq | E32: Hiu | F32: Toko Putra Bumi Berkah | G32: 9000 | H32: 675000 | I32: Cash | J32: 350000 | K32: Cash | L32: =H32-J32 -> 325000
B33: 45588 | C33: W 8882 DS | D33: Pak Rofiq | E33: Lotus | F33: Abah slamet Bojonegoro | G33: 9000 | H33: 1200000 | I33: TF | J33: 700000 | K33: Cash | L33: =H33-J33 -> 500000
B34: 45589 | C34: W 8882 DS | D34: Pak Rofiq | E34: BW | F34: Pak Ridwan Manyar | G34: 9000 | H34: 720000 | I34: Cash | J34: 350000 | K34: Cash | L34: =H34-J34 -> 370000
B35: 45590 | C35: W 8882 DS | D35: Pak Rofiq | E35: Hiu | F35: Bu prapti nganjuk | G35: 9000 | H35: 1200000 | I35: Cash | J35: 640000 | K35: Cash | L35: =H35-J35 -> 560000
B36: 45591 | C36: W 8882 DS | D36: Pak Rofiq | E36: Panah | F36: P Anwar Porong | G36: 6000 | H36: 600000 | I36: Cash | J36: 300000 | K36: Cash | L36: =H36-J36 -> 300000
B37: 45593 | C37: P 9611 GA | D37: Pak Rofiq | E37: Panah | F37: Abah Zakariya Jombang | G37: 10000 | H37: 1100000 | I37: TF | J37: 600000 | K37: Cash | L37: =H37-J37 -> 500000
B38: 45594 | C38: P 9611 GA | D38: Pak Rofiq | E38: Panah | F38: Bu iin sepanjang | G38: 10000 | H38: 750000 | I38: TF | J38: 425000 | K38: TF | L38: =H38-J38 -> 325000 | M38: 250000
B39: 45595 | C39: P 9611 GA | D39: Pak Rofiq | E39: BW (Tomat) | F39: Bu Tutik bojonegoro | G39: 9000 | H39: 1125000 | I39: Cash | J39: 640000 | K39: Cash | L39: =H39-J39 -> 485000 | M39: 30000
B40: 45596 | C40: P 9611 GA | D40: Pak Rofiq | E40: Jagung | F40: Pare | G40: 10000 | J40: 1035000 | K40: Cash | L40: =H40-J40 -> -1035000 | M40: 1050000
L41: =SUM(L18:L40) -> 9515000 | M41: =SUM(M18:M40) -> 3055000
L42: =L41-M41 -> 6460000
A44: NO | B44: TANGGAL | C44: NO. POL | D44: DRIVER | E44: MERK KEDELAI | F44: PENERIMA | G44: BERAT (kg) | H44: ONGKOSAN | I44: KET | J44: SAKU SOPIR | K44: KET | L44: SETORAN | M44: KERUSAKAN
A45: 1 | B45: 45600 | C45: P 9611 GA | D45: Pak Rofiq | E45: Panah | F45: BU Kasmi Madiun | G45: 10000 | H45: 1500000 | I45: TF | J45: 850000 | K45: Cash | L45: =H45-J45 -> 650000 | M45: 60000
...

Sheet P PRI (W8263DW)
B1: TANGGAL | C1: NO. POL | D1: DRIVER | E1: MERK KEDELAI | F1: PENERIMA | G1: BERAT (kg) | H1: ONGKOSAN | I1: KET | J1: SAKU SOPIR | K1: KET | L1: SETORAN | M1: KERUSAKAN
B2: 04 Mei | C2: W 8263 DW | D2: Pak Priyanto | M2: 5495000
B3: 07 Mei | C3: W 8263 DW | D3: Pak Priyanto | E3: Hiu | F3: P Yanto porong | G3: 9000 | H3: 810000 | I3: Cash | J3: 450000 | K3: Cash | L3: =H3-J3 -> 360000 | M3: 610000
B4: 08 Mei | C4: W 8263 DW | D4: Pak Priyanto | E4: Panah | F4: Bu iin sepanjang | G4: 9000 | H4: 675000 | I4: TF | J4: 375000 | K4: Cash | L4: =H4-J4 -> 300000
B5: 08 Mei | C5: W 8263 DW | D5: Pak Priyanto | E5: Hiu | F5: Bu iin sepanjang | G5: 9000 | H5: 675000 | I5: TF | J5: 375000 | K5: Cash | L5: =H5-J5 -> 300000
B6: 10 Mei | C6: W 8263 DW | D6: Pak Priyanto | E6: Panah | F6: Abah mif | G6: 9000 | H6: 900000 | I6: TF | J6: 350000 | K6: TF | L6: =H6-J6 -> 550000
B7: 10 Mei | C7: W 8263 DW | D7: Pak Priyanto | E7: Panah | F7: Bu tutik bojonegoro kota | G7: 9000 | H7: 1125000 | I7: Cash | J7: 640000 | K7: Cash | L7: =H7-J7 -> 485000
B8: 11 Mei | C8: W 8263 DW | D8: Pak Priyanto | E8: Super bean | F8: Bu tutik kapas | G8: 9000 | H8: 1035000 | I8: Cash | J8: 600000 | K8: Cash | L8: =H8-J8 -> 435000
B9: 13 Mei | C9: W 8263 DW | D9: Pak Priyanto | E9: Hiu | F9: Abah mif | G9: 9000 | H9: 720000 | I9: TF | J9: 350000 | K9: Cash | L9: =H9-J9 -> 370000 | M9: 607000
B10: 14 Mei | C10: W 8263 DW | D10: Pak Priyanto | E10: BW | F10: P Ridwan manyar | G10: 9000 | H10: 720000 | I10: Cash | J10: 350000 | K10: Cash | L10: =H10-J10 -> 370000
B11: 15 Mei | C11: W 8263 DW | D11: Pak Priyanto | E11: Hiu | F11: Bu prapti nganjuk | G11: 9000 | H11: 1200000 | I11: Cash | J11: 640000 | K11: Cash | L11: =H11-J11 -> 560000
B12: 17 Mei | C12: W 8263 DW | D12: Pak Priyanto | E12: Panah | F12: Abah mif | G12: 9000 | H12: 900000 | I12: TF | J12: 350000 | K12: Cash | L12: =H12-J12 -> 550000
B13: 18 Mei | C13: W 8263 DW | D13: Pak Priyanto | E13: Hiu | F13: Bu iin sepanjang | G13: 9000 | H13: 675000 | I13: TF | J13: 375000 | K13: Cash | L13: =H13-J13 -> 300000
B14: 18 Mei | C14: W 8263 DW | D14: Pak Priyanto | E14: Hiu | F14: P Yanto porong | G14: 9000 | H14: 810000 | I14: Cash | J14: 450000 | K14: Cash | L14: =H14-J14 -> 360000 | M14: 25000
B15: 20 Mei | C15: W 8263 DW | D15: Pak Priyanto | E15: Tumpi | F15: P Arif Blitar | G15: 9000 | H15: 1000000 | I15: TF | J15: 700000 | K15: Cash | L15: =H15-J15 -> 300000
B16: 21 Mei | C16: W 8263 DW | D16: Pak Priyanto | E16: Hiu | F16: Bu iin sepanjang | G16: 9000 | H16: 675000 | I16: TF | J16: 375000 | K16: TF | L16: =H16-J16 -> 300000
B17: 22 Mei | C17: W 8263 DW | D17: Pak Priyanto | E17: Panah | F17: Roni sederhana malang | G17: 8500 | H17: 1200000 | I17: TF | J17: 640000 | K17: TF | L17: =H17-J17 -> 560000
B18: 24 Mei | C18: W 8263 DW | D18: Pak Priyanto | E18: Hiu | F18: Abah mif | G18: 9000 | H18: 900000 | I18: TF | J18: 350000 | K18: TF | L18: =H18-J18 -> 550000
B19: 25 Mei | C19: W 8263 DW | D19: Pak Priyanto | E19: Hiu | F19: Bu kasmi madiun | G19: 9000 | H19: 1350000 | I19: TF | J19: 800000 | K19: TF | L19: =H19-J19 -> 550000 | M19: 725000
B20: 27 Mei | C20: W 8263 DW | D20: Pak Priyanto | E20: Panah | F20: Toko putra bumi berkah | G20: 9000 | H20: 675000 | I20: Cash | J20: 350000 | K20: Cash | L20: =H20-J20 -> 325000
B21: 28 Mei | C21: W 8263 DW | D21: Pak Priyanto | E21: Hiu | F21: Bu iin sepanjang | G21: 9000 | H21: 675000 | I21: TF | J21: 375000 | K21: Cash | L21: =H21-J21 -> 300000 | M21: 490000
B22: 29 Mei | C22: W 8263 DW | D22: Pak Priyanto | E22: BW | F22: P Ridwan manyar | G22: 9000 | H22: 720000 | I22: Cash | J22: 350000 | K22: Cash | L22: =H22-J22 -> 370000
B23: 31 Mei | C23: W 8263 DW | D23: Pak Priyanto | E23: Tulip | F23: Abah mif | G23: 10000 | H23: 1000000 | I23: TF | J23: 375000 | K23: Cash | L23: =H23-J23 -> 625000
B24: 31 Mei | C24: W 8263 DW | D24: Pak Priyanto | E24: Lotus | F24: Bu yatini | G24: 8500 | H24: 1400000 | I24: TF | J24: 900000 | K24: TF | L24: =H24-J24 -> 500000
L25: =SUM(L3:L24) -> 9320000 | M25: =SUM(M2:M24) -> 7952000
L26: =L25-M25 -> 1368000
B28: TANGGAL | C28: NO. POL | D28: DRIVER | E28: MERK KEDELAI | F28: PENERIMA | G28: BERAT (kg) | H28: ONGKOSAN | I28: KET | J28: SAKU SOPIR | K28: KET | L28: SETORAN | M28: KERUSAKAN
B29: 03 Juni | C29: W 8263 DW | D29: P Priyanto | E29: Hiu | F29: Bu kasmi madiun | G29: 9000 | H29: 1350000 | I29: TF | J29: 800000 | K29: Cash | L29: =H29-J29 -> 550000 | M29: 945000
B30: 04 Juni | C30: W 8263 DW | D30: P Priyanto | E30: Lotus | F30: Bu prapti nganjuk | G30: 9000 | H30: 1200000 | I30: Cash | J30: 640000 | K30: Cash | L30: =H30-J30 -> 560000
B31: 05 Juni | C31: W 8263 DW | D31: P Priyanto | E31: TSC | F31: P Ridwan manyar | G31: 9000 | H31: 720000 | I31: Cash | J31: 350000 | K31: Cash | L31: =H31-J31 -> 370000
B32: 06 Juni | C32: W 8263 DW | D32: P Priyanto | E32: Lotus | F32: P iwan bojonegoro | G32: 9000 | H32: 1170000 | I32: Cash | J32: 640000 | K32: Cash | L32: =H32-J32 -> 530000
B33: 07 Juni | C33: W 8263 DW | D33: P Priyanto | E33: Panah | F33: Toko putra bumi berkah | G33: 9000 | H33: 675000 | I33: Cash | J33: 350000 | K33: Cash | L33: =H33-J33 -> 325000
B34: 08 Juni | C34: W 8263 DW | D34: P Priyanto | E34: Hiu | F34: Bu kasmi madiun | G34: 9000 | H34: 1350000 | I34: TF | J34: 800000 | K34: Cash | L34: =H34-J34 -> 550000
B35: 10 Juni | C35: W 8263 DW | D35: P Priyanto | E35: Lotus | F35: Bu iin sepanjang | G35: 9000 | H35: 675000 | I35: TF | J35: 375000 | K35: TF | L35: =H35-J35 -> 300000
B36: 10 Juni | C36: W 8263 DW | D36: P Priyanto | E36: Lotus | F36: Roni sederhana malang | G36: 9000 | H36: 1200000 | I36: Cash | J36: 640000 | K36: TF | L36: =H36-J36 -> 560000
B37: 12 Juni | C37: W 8263 DW | D37: P Priyanto | E37: Panah | F37: P Yanto porong | G37: 9000 | H37: 810000 | I37: Cash | J37: 450000 | K37: Cash | L37: =H37-J37 -> 360000
B38: 13 Juni | C38: W 8263 DW | D38: P Priyanto | E38: Super bean | F38: P Ridwan manyar | G38: 9000 | H38: 720000 | I38: Cash | J38: 350000 | K38: Cash | L38: =H38-J38 -> 370000
B39: 13 Juni | C39: W 8263 DW | D39: P Priyanto | E39: Panah | F39: Abah mif | G39: 9000 | H39: 900000 | I39: TF | J39: 350000 | K39: Cash | L39: =H39-J39 -> 550000
B40: 14 Juni | C40: W 8263 DW | D40: P Priyanto | E40: Lotus | F40: Abah mif | G40: 9000 | H40: 900000 | I40: TF | J40: 350000 | K40: Cash | L40: =H40-J40 -> 550000
B41: 14 Juni | C41: W 8263 DW | D41: P Priyanto | E41: Lotus | F41: Abah slamet | G41: 9000 | H41: 1215000 | I41: TF | J41: 700000 | K41: Cash | L41: =H41-J41 -> 515000
...

Sheet P AJI (N8517EW)
B1: TANGGAL | C1: NO. POL | D1: DRIVER | E1: MERK KEDELAI | F1: PENERIMA | G1: BERAT (kg) | H1: ONGKOSAN | J1: SAKU SOPIR | L1: SETORAN | M1: KERUSAKAN
B2: 45078 | C2: S 9157 HI | D2: PAK AJI | E2: JEMPOL SIP | F2: TOKO SEDERHANA MALANG | G2: 8500 | H2: 1130000 | J2: 640000 | L2: =H2-J2 -> 490000 | M2: 140000
B3: 45080 | C3: S 9157 HI | D3: PAK AJI | E3: PANAH | F3: KOPTI WAHYU SATRIA MALANG | G3: 8500 | H3: 1100000 | J3: 640000 | L3: =H3-J3 -> 460000 | M3: 100000
B4: 45082 | C4: S 9157 HI | D4: PAK AJI | E4: PANAH | F4: PAK JAMIL | G4: 9000 | H4: 1400000 | J4: 900000 | L4: =H4-J4 -> 500000
B5: 45083 | C5: S 9157 HI | D5: PAK AJI | E5: PANAH | F5: ABAH PRANOTO | G5: 8500 | H5: 1300000 | J5: 850000 | L5: =H5-J5 -> 450000
B6: 45085 | C6: S 9157 HI | D6: PAK AJI | E6: LOTUS | F6: PAK SLAMET TOBO | G6: 9000 | H6: 1215000 | J6: 700000 | L6: =H6-J6 -> 515000
B7: 45086 | C7: S 9157 HI | D7: PAK AJI | E7: PANAH | F7: KAMDANI | G7: 9000 | H7: 1200000 | J7: 640000 | L7: =H7-J7 -> 560000 | M7: 200000
B8: 45087 | C8: S 9157 HI | D8: PAK AJI | E8: JEMPOL SIP | F8: PAK HERWANTO | G8: 9000 | H8: 765000 | J8: 450000 | L8: =H8-J8 -> 315000
B9: 45089 | C9: S 9157 HI | D9: PAK AJI | E9: SUPERBIN | F9: BU TUTIK | H9: 990000 | J9: 550000 | L9: =H9-J9 -> 440000
B10: 45090 | C10: S 9157 HI | D10: PAK AJI | E10: JEMPOL SIP | F10: TOKO SEDERHANA MALANG | G10: 8500 | H10: 1130000 | J10: 640000 | L10: =H10-J10 -> 490000
B11: 45092 | C11: S 9157 HI | D11: PAK AJI | E11: LOTUS | F11: PAK SLAMET TOBO | G11: 9000 | H11: 1215000 | J11: 700000 | L11: =H11-J11 -> 515000
B12: 45093 | C12: S 9157 HI | D12: PAK AJI | E12: LOTUS | F12: KOPTI GIRI JAYA GRESIK | G12: 9000 | H12: 720000 | J12: 350000 | L12: =H12-J12 -> 370000
B13: 45093 | C13: S 9157 HI | D13: PAK AJI | E13: LOTUS | F13: TOKO BUMI BERKAH | G13: 9000 | H13: 675000 | J13: 350000 | L13: =H13-J13 -> 325000
B14: 45094 | C14: S 9157 HI | D14: PAK AJI | E14: PANAH | F14: PAK KAMDANI | G14: 8500 | H14: 1200000 | J14: 640000 | L14: =H14-J14 -> 560000
B15: 45097 | C15: S 9157 HI | D15: PAK AJI | E15: JEMPOL SIP | F15: ABAH KOHAR BOJONEGORO | H15: 975000 | J15: 500000 | L15: =H15-J15 -> 475000
B16: 45098 | C16: S 9157 HI | D16: PAK AJI | E16: JEMPOL SIP | F16: ABAH KOHAR BOJONEGORO | H16: 975000 | J16: 500000 | L16: =H16-J16 -> 475000
B17: 45099 | E17: LOTUS | F17: KOPTI GIRI JAYA GRESIK | H17: 720000 | J17: 350000 | L17: =H17-J17 -> 370000
B18: 45100 | F18: ABAH PRANOTO | H18: 1300000 | J18: 850000 | L18: =H18-J18 -> 450000
B19: 45100 | C19: S 9157 HI | D19: PAK AJI | E19: PANAH | F19: KOPTI GIRI JAYA GRESIK | G19: 9000 | H19: 720000 | J19: 350000 | L19: =H19-J19 -> 370000
B20: 45103 | C20: S 9157 HI | D20: PAK AJI | E20: LOTUS | F20: TOKO SEDERHANA MALANG | G20: 8500 | H20: 1200000 | J20: 640000 | L20: =H20-J20 -> 560000
B21: 45104 | C21: S 9157 HI | D21: PAK AJI | E21: PLASTIK | F21: KOH HERI JEMBER | H21: 1500000 | J21: 800000 | L21: =H21-J21 -> 700000
L22: =SUM(L1:L21) -> 9390000 | M22: =SUM(M1:M21) -> 440000
L23: =L22-M22 -> 8950000
B25: TANGGAL | C25: NO. POL | D25: DRIVER | E25: MERK KEDELAI | F25: PENERIMA | G25: BERAT (kg) | H25: ONGKOSAN | J25: SAKU SOPIR | L25: SETORAN | M25: KERUSAKAN
B26: 45108 | C26: S 9157 HI | D26: Pak Aji | E26: HIU | F26: Pak Iwan Bojonegoro Kota | G26: 9000 | H26: 1080000 | J26: 640000 | L26: =H26-J26 -> 440000
B27: 45111 | C27: S 9157 HI | D27: Pak Aji | E27: Lotus | F27: Roni Sederhana Malang Blimbing | G27: 8500 | H27: 1200000 | J27: 640000 | L27: =H27-J27 -> 560000
B28: 45112 | C28: S 9157 HI | D28: Pak Aji | E28: Lotus | F28: Pak Ramen Ngawi | G28: 9000 | H28: 1450000 | J28: 900000 | L28: =H28-J28 -> 550000 | M28: 140000
B29: 45113 | C29: S 9157 HI | D29: Pak Aji | E29: Lotus | F29: Abah Mif Kopti Giri Jaya | G29: 9000 | H29: 720000 | J29: 350000 | L29: =H29-J29 -> 370000
B30: 45114 | C30: S 9157 HI | D30: Pak Aji | E30: Lotus | F30: Abah Slamet Bojonegoro Kalitidu | G30: 9000 | H30: 1215000 | J30: 700000 | L30: =H30-J30 -> 515000
B31: 45115 | C31: S 9157 HI | D31: Pak Aji | E31: Panah Biru | F31: Bu Astuti Bojonegoro Kota | G31: 9000 | H31: 1125000 | J31: 640000 | L31: =H31-J31 -> 485000 | M31: 70000
B32: 45117 | C32: S 9157 HI | D32: Pak Aji | E32: Lotus | F32: Abah Slamet Bojonegoro Kalitidu | G32: 9000 | H32: 1215000 | J32: 700000 | L32: =H32-J32 -> 515000
B33: 45118 | C33: S 9157 HI | D33: Pak Aji | L33: =H33-J33 -> 0 | M33: 1100000
B34: 45119 | C34: S 9157 HI | D34: Pak Aji | E34: Panah Biru | F34: Bu kasmi madiun | G34: 9000 | H34: 1350000 | J34: 800000 | L34: =H34-J34 -> 550000
B35: 45120 | C35: S 9157 HI | D35: Pak Aji | E35: Lotus | F35: Bu prapti nganjuk | G35: 9000 | H35: 1200000 | J35: 640000 | L35: =H35-J35 -> 560000
B36: 45122 | C36: S 9157 HI | D36: Pak Aji | E36: Lotus | F36: Toko sederhana malang | G36: 8500 | H36: 1200000 | J36: 640000 | L36: =H36-J36 -> 560000 | M36: 250000
B37: 45124 | C37: S 9157 HI | D37: Pak Aji | E37: Lotus | F37: Abah kohar bojonegoro | G37: 9000 | H37: 975000 | J37: 500000 | L37: =H37-J37 -> 475000
B38: 45125 | C38: S 9157 HI | D38: Pak Aji | E38: Jempol sip | F38: Toko sederhana malang | G38: 8500 | H38: 1200000 | J38: 640000 | L38: =H38-J38 -> 560000
B39: 45127 | C39: S 9157 HI | D39: Pak Aji | E39: Lotus | F39: Abah Slamet Bojonegoro Kalitidu | G39: 9000 | H39: 1215000 | J39: 700000 | L39: =H39-J39 -> 515000
B40: 45127 | C40: S 9157 HI | D40: Pak Aji | E40: Lotus | F40: Toko bumi berkah | G40: 9000 | H40: 675000 | J40: 350000 | L40: =H40-J40 -> 325000
B41: 45128 | C41: S 9157 HI | D41: Pak Aji | E41: Lotus | F41: Abah khohar | G41: 9000 | H41: 975000 | J41: 500000 | L41: =H41-J41 -> 475000
...

Sheet P NARTO (A9108A)
B1: TANGGAL | C1: NO. POL | D1: DRIVER | E1: MERK KEDELAI | F1: PENERIMA | G1: BERAT (kg) | H1: ONGKOSAN | I1: KET | J1: SAKU SOPIR | K1: KET | L1: SETORAN | M1: KERUSAKAN
M2: 900000
B3: 27 Juni 24 | C3: S 8329 WI | D3: P Agik | E3: Jempol Sip | F3: Abah slamet | G3: 9000 | H3: 1215000 | I3: TF | J3: 700000 | K3: Cash | L3: =H3-J3 -> 515000
B4: 28 Juni 24 | C4: S 8329 WI | D4: P Agik | E4: Panah | F4: Bu tutik kapas | G4: 9000 | H4: 1035000 | I4: Cash | J4: 600000 | K4: Cash | L4: =H4-J4 -> 435000
B5: 29 Juni 24 | C5: S 8329 WI | D5: P Agik | E5: Panah | F5: Bu kasmi madiun | G5: 9000 | H5: 1350000 | I5: TF | J5: 800000 | K5: Cash | L5: =H5-J5 -> 550000 | M5: 9660000
L6: =SUM(L2:L5) -> 1500000 | M6: =SUM(M2:M5) -> 10560000
L7: =L6-M6 -> -9060000
B9: TANGGAL | C9: NO. POL | D9: DRIVER | E9: MERK KEDELAI | F9: PENERIMA | G9: BERAT (kg) | H9: ONGKOSAN | I9: KET | J9: SAKU SOPIR | K9: KET | L9: SETORAN | M9: KERUSAKAN
B10: 01 Juli | C10: S 8329 WI | D10: P Agik | E10: Jempol sip | F10: Bu tutik Bojonegoro kota | G10: 9000 | H10: 1125000 | I10: Cash | J10: 640000 | K10: Cash | L10: =H10-J10 -> 485000 | M10: 5472000
B11: 02 Juli | C11: S 8329 WI | D11: P Agik | E11: Jempol sip | F11: Abah slamet tobo bojonegoro | G11: 9000 | H11: 1215000 | I11: TF | J11: 775000 | K11: Cash | L11: =H11-J11 -> 440000
B12: 04 Juli | C12: S 8329 WI | D12: P Agik | E12: Jempol sip | F12: Bu tutik Bojonegoro kota | G12: 9000 | H12: 1125000 | I12: Cash | J12: 640000 | K12: Cash | L12: =H12-J12 -> 485000
B13: 06 Juli | C13: S 8329 WI | D13: P Agik | E13: Panah | F13: Bu tutik Bojonegoro kota | G13: 9000 | H13: 1125000 | I13: Cash | J13: 640000 | K13: Cash | L13: =H13-J13 -> 485000
B14: 08 Juli | C14: S 8329 WI | D14: P Agik | E14: Jempol sip | F14: Bu tutik Bojonegoro kota | G14: 9000 | H14: 1125000 | I14: Cash | J14: 640000 | K14: Cash | L14: =H14-J14 -> 485000
B15: 09 Juli | C15: S 8329 WI | D15: P Agik | E15: Jempol sip | F15: Bu tutik Bojonegoro kota | G15: 9000 | H15: 1125000 | I15: Cash | J15: 640000 | K15: Cash | L15: =H15-J15 -> 485000
B16: 10 Juli | C16: S 8329 WI | D16: P Agik | E16: Hiu | F16: Bu kasmi madiun | G16: 10000 | H16: 1500000 | I16: TF | J16: 850000 | K16: Cash | L16: =H16-J16 -> 650000
B17: 11 Juli | C17: S 8329 WI | D17: P Agik | E17: Jempol sip | F17: P Jamil ngawi | G17: 9000 | H17: 1400000 | I17: Cash | J17: 900000 | K17: Cash | L17: =H17-J17 -> 500000
B18: 12 Juli | C18: S 8329 WI | D18: P Agik | E18: Jempol sip | F18: Bu tutik Bojonegoro kota | G18: 9000 | H18: 1125000 | I18: Cash | J18: 640000 | K18: Cash | L18: =H18-J18 -> 485000
B19: 13 Juli | C19: S 8329 WI | D19: P Agik | E19: Panah | F19: P Ramin Ngawi | G19: 9000 | H19: 1450000 | I19: TF | J19: 900000 | K19: Cash | L19: =H19-J19 -> 550000
B20: 15 Juli | C20: S 8329 WI | D20: P Agik | E20: Jempol sip | F20: Bu tutik sumber rejo | G20: 9000 | H20: 990000 | I20: Cash | J20: 550000 | K20: TF | L20: =H20-J20 -> 440000
B21: 16 Juli | C21: S 8329 WI | D21: P Agik | E21: Jempol sip | F21: Toko Putra bumi Berkah | G21: 4500 | H21: 338000 | I21: Cash | J21: 171000 | K21: Cash | L21: =H21-J21 -> 167000
B22: 16 Juli | C22: S 8329 WI | D22: P Agik | E22: Jempol sip | F22: P Hasan sukodono | G22: 4500 | H22: 400000 | I22: Cash | J22: 254000 | K22: Cash | L22: =H22-J22 -> 146000 | M22: 440000
B23: 17 Juli | C23: S 8329 WI | D23: P Agik | E23: Panah | F23: P Ramin Ngawi | G23: 9000 | H23: 1440000 | I23: TF | J23: 900000 | K23: Cash | L23: =H23-J23 -> 540000
B24: 18 Juli | C24: S 8329 WI | D24: P Agik | E24: Jempol sip | F24: Abah slamet tobo bojonegoro | G24: 9000 | H24: 1215000 | I24: TF | J24: 775000 | K24: TF | L24: =H24-J24 -> 440000
B25: 20 Juli | C25: S 8329 WI | D25: P Agik | E25: Hiu | F25: Bu qusaimah pare | G25: 9000 | H25: 1100000 | I25: TF | J25: 650000 | K25: TF | L25: =H25-J25 -> 450000
B26: 22 Juli | C26: S 8329 WI | D26: P Agik | E26: Jempol sip | F26: P Anwar porong | G26: 9000 | H26: 800000 | I26: TF | J26: 450000 | K26: TF | L26: =H26-J26 -> 350000 | M26: 315000
B27: 23 Juli | C27: S 8329 WI | D27: P Agik | E27: Tulip | F27: Toko Putra bumi Berkah | G27: 10000 | H27: 800000 | I27: Cash | J27: 375000 | K27: TF | L27: =H27-J27 -> 425000
B28: 23 Juli | C28: S 8329 WI | D28: P Agik | E28: Panah | F28: Bu tutik bojonegoro kapas | G28: 9000 | H28: 1035000 | I28: Cash | J28: 600000 | K28: Cash | L28: =H28-J28 -> 435000
B29: 24 Juli | C29: S 8329 WI | D29: P Agik | E29: Lotus | F29: Mba tiwuk nganjuk | G29: 9000 | H29: 1170000 | I29: Cash | J29: 640000 | K29: Cash | L29: =H29-J29 -> 530000
B30: 25 Juli | C30: S 8329 WI | D30: P Agik | E30: BW | F30: P Ridwan manyar | G30: 9000 | H30: 720000 | I30: Cash | J30: 350000 | K30: Cash | L30: =H30-J30 -> 370000
B31: 25 Juli | C31: S 8329 WI | D31: P Agik | E31: Panah | F31: Abah parnoto blitar | G31: 9000 | H31: 1350000 | I31: Cash | J31: 875000 | K31: Cash | L31: =H31-J31 -> 475000
B32: 27 Juli | C32: S 8329 WI | D32: P Agik | E32: Lotus | F32: Abah parnoto blitar | G32: 9000 | H32: 1350000 | I32: Cash | J32: 875000 | K32: Cash | L32: =H32-J32 -> 475000 | M32: 2080000
B33: 29 Juli | C33: S 8329 WI | D33: P Agik | E33: Jempol sip | F33: Toko Putra bumi Berkah | G33: 9000 | H33: 675000 | I33: Cash | J33: 425000 | K33: Cash | L33: =H33-J33 -> 250000
B34: 29 Juli | C34: S 8329 WI | D34: P Agik | E34: Panah | F34: Bu tutik bojonegoro kapas | G34: 9000 | H34: 1035000 | I34: TF | J34: 600000 | K34: Cash | L34: =H34-J34 -> 435000
B35: 30 Juli | C35: S 8329 WI | D35: P Agik | E35: Lotus | F35: Bu tutik bojonegoro sumber rejo | G35: 9000 | H35: 990000 | I35: TF | J35: 550000 | K35: TF | L35: =H35-J35 -> 440000
B36: 31 Juli | C36: S 8329 WI | D36: P Agik | E36: Panah | F36: Bu tutik bojonegoro kota | G36: 9000 | H36: 1125000 | I36: TF | J36: 640000 | K36: TF | L36: =H36-J36 -> 485000
L37: =SUM(L10:L36) -> 11903000 | M37: =SUM(M9:M36) -> 8307000
L38: =L37-M37 -> 3596000
B40: TANGGAL | C40: NO. POL | D40: DRIVER | E40: MERK KEDELAI | F40: PENERIMA | G40: BERAT (kg) | H40: ONGKOSAN | I40: KET | J40: SAKU SOPIR | K40: KET | L40: SETORAN | M40: KERUSAKAN
B41: 1 Agustus | C41: S 8329 WI | D41: P Agik | E41: Panah | F41: Abah muh madura | G41: 9000 | H41: 1400000 | I41: Cash | J41: 850000 | K41: TF | L41: =H41-J41 -> 550000 | M41: 0
B42: 2 Agustus | C42: S 8329 WI | D42: P Agik | E42: Panah | F42: Bu prapti nganjuk | G42: 9000 | H42: 1200000 | I42: TF | J42: 640000 | K42: TF | L42: =H42-J42 -> 560000 | M42: 0
...

Sheet P SENO (S9509NG)
B1: TANGGAL | C1: NO. POL | D1: DRIVER | E1: MERK KEDELAI | F1: PENERIMA | G1: BERAT (kg) | H1: ONGKOSAN | I1: KET | J1: SAKU SOPIR | K1: KET | L1: SETORAN | M1: KERUSAKAN
B2: 23 Juli | C2: N 8613 EW | D2: M Endris | E2: Hiu | F2: Bu kasmi madiun | G2: 10000 | H2: 1500000 | I2: Cash | J2: 850000 | K2: Cash | L2: =H2-J2 -> 650000
B3: 24 Juli | C3: N 8613 EW | D3: M Endris | E3: Hiu | F3: Mba Nur Kopti Mojokerto | G3: 9000 | H3: 765000 | I3: TF | J3: 450000 | K3: TF | L3: =H3-J3 -> 315000
B4: 25 Juli | C4: N 8613 EW | D4: M Endris | E4: Panah | F4: P Yanto porong | G4: 10000 | H4: 900000 | I4: TF | J4: 500000 | K4: Cash | L4: =H4-J4 -> 400000
B5: 26 Juli | C5: N 8613 EW | D5: M Endris | E5: Hiu | F5: P Yanto porong | G5: 10000 | H5: 900000 | I5: TF | J5: 500000 | K5: Cash | L5: =H5-J5 -> 400000
B6: 27 Juli | C6: N 8613 EW | D6: M Endris | E6: Panah | F6: Bu tutik bojonegoro kota | G6: 9000 | H6: 1125000 | I6: Cash | J6: 640000 | K6: Cash | L6: =H6-J6 -> 485000
B7: 29 Juli | C7: N 8613 EW | D7: M Endris | E7: Lotus | F7: P Jamil ngawi | G7: 9000 | H7: 1395000 | I7: Cash | J7: 900000 | K7: Cash | L7: =H7-J7 -> 495000
B8: 30 Juli | C8: N 8613 EW | D8: M Endris | E8: Lotus | F8: P Jamil ngawi | G8: 9000 | H8: 1395000 | I8: Cash | J8: 900000 | K8: TF | L8: =H8-J8 -> 495000 | M8: 81000
L9: =SUM(L2:L8) -> 3240000 | M9: =SUM(M2:M8) -> 81000
L10: =L9-M9 -> 3159000
B12: TANGGAL | C12: NO. POL | D12: DRIVER | E12: MERK KEDELAI | F12: PENERIMA | G12: BERAT (kg) | H12: ONGKOSAN | I12: KET | J12: SAKU SOPIR | K12: KET | L12: SETORAN | M12: KERUSAKAN
B13: 1 Agustus | C13: N 8613 EW | D13: M Endris | E13: Lotus | F13: P Ridwan manyar | G13: 9000 | H13: 720000 | I13: Cash | J13: 350000 | K13: Cash | L13: =H13-J13 -> 370000 | M13: 255000
B14: 3 Agustus | C14: N 8613 EW | D14: M Endris | E14: Jempol sip | F14: P Anwar porong | G14: 8000 | H14: 800000 | I14: Cash | J14: 450000 | K14: Cash | L14: =H14-J14 -> 350000 | M14: 0
B15: 5 Agustus | C15: N 8613 EW | D15: M Endris | E15: Bola | F15: P Anwar porong | G15: 9000 | H15: 810000 | I15: TF | J15: 400000 | K15: Cash | L15: =H15-J15 -> 410000 | M15: 0
B16: 6 Agustus | C16: N 8613 EW | D16: M Endris | E16: Lotus | F16: P Ridwan manyar | G16: 9000 | H16: 720000 | I16: TF | J16: 350000 | K16: Cash | L16: =H16-J16 -> 370000 | M16: 0
B17: 7 Agustus | C17: N 8613 EW | D17: M Endris | E17: Panah | F17: P Yanto porong | G17: 10000 | H17: 900000 | I17: TF | J17: 500000 | K17: Cash | L17: =H17-J17 -> 400000 | M17: 0
B18: 7 Agustus | C18: N 8613 EW | D18: M Endris | E18: Panah | F18: Bu tutik bojonegoro | G18: 9000 | H18: 1125000 | I18: Cash | J18: 640000 | K18: Cash | L18: =H18-J18 -> 485000 | M18: 0
B19: 8 Agustus | C19: N 8613 EW | D19: M Endris | E19: Panah | F19: Mba tiwuk nganjuk | G19: 9000 | H19: 1170000 | I19: Cash | J19: 640000 | K19: Cash | L19: =H19-J19 -> 530000 | M19: 0
B20: 10 Agustus | C20: N 8613 EW | D20: M Endris | E20: P Arif blitar | F20: Bu kasmi | G20: 10000 | H20: 1500000 | I20: TF | J20: 850000 | K20: Cash | L20: =H20-J20 -> 650000 | M20: 271000
B21: 13 Agustus | C21: N 8613 EW | D21: M Endris | E21: Tumpi Panah | F21: P Arif blitar | G21: 6749.5 | H21: 2024850 | I21: Cash | J21: 900000 | K21: Cash | L21: =H21-J21 -> 1124850 | M21: 725000
B22: 14 Agustus | C22: N 8613 EW | D22: M Endris | E22: Tumpi Panah | F22: P Arif blitar | G22: 6597.5 | H22: 1979250 | I22: Cash | J22: 900000 | K22: Cash | L22: =H22-J22 -> 1079250 | M22: 0
B23: 15 Agustus | C23: N 8613 EW | D23: M Endris | E23: Panah | F23: Bu tutik bojonegoro kapas | G23: 9000 | H23: 1035000 | I23: Cash | J23: 600000 | K23: Cash | L23: =H23-J23 -> 435000 | M23: 0
B24: 16 Agustus | C24: N 8613 EW | D24: M Endris | E24: Panah | F24: P Anwar porong | G24: 9000 | H24: 900000 | I24: TF | J24: 400000 | K24: Cash | L24: =H24-J24 -> 500000 | M24: 0
B25: 18 Agustus | C25: N 8613 EW | D25: M Endris | F25: Mba tiwuk nganjuk | L25: 200000 | M25: 0
B26: 20 Agustus | C26: N 8613 EW | D26: M Endris | E26: Lotus | G26: 9000 | H26: 1170000 | I26: Cash | J26: 640000 | K26: Cash | L26: =H26-J26 -> 530000 | M26: 0
B27: 21 Agustus | C27: N 8613 EW | D27: M Endris | E27: Super bean | F27: P Ridwan manyar | G27: 9000 | H27: 720000 | I27: Cash | J27: 350000 | K27: Cash | L27: =H27-J27 -> 370000 | M27: 235000
B28: 22 Agustus | C28: N 8613 EW | D28: M Endris | E28: Panah | F28: Abah parnoto blitar | G28: 9000 | H28: 1350000 | I28: Cash | J28: 875000 | K28: Cash | L28: =H28-J28 -> 475000 | M28: 625000
B29: 24 Agustus | C29: N 8613 EW | D29: M Endris | E29: Hiu | F29: P Yanto porong | G29: 9000 | H29: 810000 | I29: TF | J29: 450000 | K29: Cash | L29: =H29-J29 -> 360000 | M29: 0
B30: 25 Agustus | C30: N 8613 EW | D30: M Endris | E30: Pakan Ternak | F30: Srengat Blitar | G30: 10420 | H30: 1458800 | I30: TF | J30: 1000000 | K30: TF | L30: =H30-J30 -> 458800 | M30: 0
B31: 26 Agustus | C31: N 8613 EW | D31: M Endris | E31: Panah | F31: Bu tutik Kapas | G31: 9000 | H31: 1035000 | I31: Cash | J31: 600000 | K31: Cash | L31: =H31-J31 -> 435000 | M31: 2254000
B32: 27 Agustus | C32: N 8613 EW | D32: M Endris | E32: Pakan Ternak | F32: Pujon | G32: 9000 | H32: 1100000 | I32: TF | J32: 725000 | K32: Cash | L32: =H32-J32 -> 375000 | M32: 0
B33: 30 Agustus | C33: N 8613 EW | D33: M Endris | E33: Hiu | F33: Bu iin sepanjang | G33: 9000 | H33: 675000 | I33: TF | J33: 375000 | K33: Cash | L33: =H33-J33 -> 300000 | M33: 50000
B34: 31 Agustus | C34: N 8613 EW | D34: M Endris | E34: Panah | F34: Bu tutik bojonegoro | G34: 9000 | H34: 1035000 | I34: Cash | J34: 600000 | K34: Cash | L34: =H34-J34 -> 435000 | M34: 0
L35: =SUM(L13:L34) -> 10642900 | M35: =SUM(M13:M33) -> 4415000
L36: =L35-M35 -> 6227900
B38: TANGGAL | C38: NO. POL | D38: DRIVER | E38: MERK KEDELAI | F38: PENERIMA | G38: BERAT (kg) | H38: ONGKOSAN | I38: KET | J38: SAKU SOPIR | K38: KET | L38: SETORAN | M38: KERUSAKAN
B39: 45537 | C39: N 8613 EW | D39: M Endris | E39: Bola | F39: P Anwar porong | G39: 8000 | H39: 800000 | I39: TF | J39: 400000 | K39: Cash | L39: =H39-J39 -> 400000 | M39: 1695000
B40: 45538 | C40: N 8613 EW | D40: M Endris | E40: Lotus | F40: Abah slamet tobo | G40: 9000 | H40: 1215000 | I40: TF | J40: 700000 | K40: Cash | L40: =H40-J40 -> 515000
B41: 45539 | C41: N 8613 EW | D41: M Endris | E41: Jempol Sip | F41: Abah slamet tobo | G41: 9000 | H41: 1215000 | I41: TF | J41: 750000 | K41: Cash | L41: =H41-J41 -> 465000
B42: 45540 | C42: N 8613 EW | D42: M Endris | E42: Hiu | F42: P Yanto porong | G42: 10000 | H42: 900000 | I42: TF | J42: 500000 | K42: TF | L42: =H42-J42 -> 400000
...

Sheet P YOYOK (A9379CO)
A1: NO | B1: TANGGAL | C1: NO. POL | D1: DRIVER | E1: MERK KEDELAI | F1: PENERIMA | G1: BERAT (kg) | H1: ONGKOSAN | I1: KET | J1: SAKU SOPIR | K1: KET | L1: SETORAN | M1: KERUSAKAN
A2: 1 | B2: 45681 | C2: A 8379 CO | D2: Pak Yoyok | E2: hiu | F2: bu kasmi madiun | G2: 10000 | H2: 1500000 | I2: tf | J2: 850000 | K2: cash | L2: =H2-J2 -> 650000
A3: 2 | B3: 45682 | C3: A 8379 CO | D3: Pak Yoyok | E3: tulip | F3: abah slamet tobo | G3: 9000 | H3: 1215000 | I3: tf | J3: 725000 | K3: cash | L3: =H3-J3 -> 490000 | M3: 40000
A4: 3 | B4: 45682 | C4: A 8379 CO | D4: Pak Yoyok | E4: panah | F4: bu yeni ngawi | G4: 10000 | H4: 1500000 | I4: tf | J4: 975000 | K4: cash | L4: =H4-J4 -> 525000 | M4: 1126000 | N4: aku kurang 1000
L6: =SUM(L2:L5) -> 1665000 | M6: =SUM(M2:M4) -> 1166000
L7: =L6-M6 -> 499000
A9: NO | B9: TANGGAL | C9: NO. POL | D9: DRIVER | E9: MERK KEDELAI | F9: PENERIMA | G9: BERAT (kg) | H9: ONGKOSAN | I9: KET | J9: SAKU SOPIR | K9: KET | L9: SETORAN | M9: KERUSAKAN
A10: 1 | B10: 45689 | C10: A 8379 CO | D10: Pak Yoyok | E10: hiu | F10: Bu kasmi madiun | G10: 10000 | H10: 1500000 | I10: tf | J10: 850000 | K10: tf | L10: =H10-J10 -> 650000 | M10: 1150000
A11: 2 | B11: 45692 | C11: A 8379 CO | D11: Pak Yoyok | E11: hiu + ragi 10 | F11: Bu kasmi madiun | G11: 10000 | H11: 1500000 | I11: tf | J11: 850000 | K11: cash | L11: =H11-J11 -> 650000 | M11: 436000
A12: 3 | B12: 45693 | C12: A 8379 CO | D12: Pak Yoyok | E12: pakan ternak | F12: p dhion blitar | G12: 6000 | H12: 1400000 | I12: tf | J12: 640000 | K12: tf | L12: =H12-J12 -> 760000
A13: 4 | B13: 45694 | C13: A 8379 CO | D13: Pak Yoyok | E13: bola | F13: p eko turen | G13: 9000 | H13: 1350000 | I13: tf | J13: 780000 | K13: tf | L13: =H13-J13 -> 570000
A14: 5 | B14: 45695 | C14: A 8379 CO | D14: Pak Yoyok | E14: hiu | F14: Bu kasmi madiun | G14: 10000 | H14: 1500000 | I14: tf | J14: 850000 | K14: tf | L14: =H14-J14 -> 650000 | M14: 588000
A15: 6 | B15: 45696 | C15: A 8379 CO | D15: Pak Yoyok | E15: hiu | F15: toko putra bumi berkah | G15: 10000 | H15: 750000 | I15: cash | J15: 400000 | K15: cash | L15: =H15-J15 -> 350000 | M15: 455000
A16: 7 | B16: 45698 | C16: A 8379 CO | D16: Pak Yoyok | E16: lotus | F16: bu prapti nganjuk | G16: 9000 | H16: 1200000 | I16: cash | J16: 640000 | K16: cash | L16: =H16-J16 -> 560000 | M16: 60000
A17: 8 | B17: 45699 | C17: A 8379 CO | D17: Pak Yoyok | E17: hiu | F17: Bu kasmi madiun | G17: 10000 | H17: 1500000 | I17: tf | J17: 850000 | K17: cash | L17: =H17-J17 -> 650000 | M17: 100000
A18: 9 | B18: 45702 | C18: A 8379 CO | D18: Pak Yoyok | E18: lotus | F18: p saiku malang | G18: 9000 | H18: 1305000 | I18: tf | J18: 725000 | K18: cash | L18: =H18-J18 -> 580000
A19: 10 | B19: 45705 | C19: A 8379 CO | D19: Pak Yoyok | E19: hiu + ragi 4 | F19: bu nur mojokerto | G19: 9000 | H19: 765000 | I19: tf | J19: 450000 | K19: cash | L19: =H19-J19 -> 315000 | M19: 245000
A20: 11 | B20: 45707 | C20: A 8379 CO | D20: Pak Yoyok | E20: bola | F20: p eko turen | G20: 10000 | H20: 1500000 | I20: tf | J20: 830000 | K20: cash | L20: =H20-J20 -> 670000
A21: 12 | B21: 45709 | C21: A 8379 CO | D21: Pak Yoyok | E21: hiu | F21: bu kasmi madiun | G21: 10000 | H21: 1500000 | I21: tf | J21: 850000 | K21: cash | L21: =H21-J21 -> 650000
A22: 13 | B22: 45710 | C22: A 8379 CO | D22: Pak Yoyok | E22: lotus | F22: toko putra bumi berkah | G22: 9000 | H22: 675000 | I22: cash | J22: 350000 | K22: cash | L22: =H22-J22 -> 325000 | M22: 55000
A23: 14 | B23: 45712 | C23: A 8379 CO | D23: Pak Yoyok | E23: hiu + ragi 10 | F23: bu kasmi madiun | G23: 10000 | H23: 1500000 | I23: tf | J23: 850000 | K23: cash | L23: =H23-J23 -> 650000 | M23: 3792000 | N23: nota dibapak
A24: 15 | B24: 45713 | C24: A 8379 CO | D24: Pak Yoyok | E24: hiu | F24: p kasan sukodono | G24: 9000 | H24: 700000 | I24: tf | J24: 375000 | K24: cash | L24: =H24-J24 -> 325000
A25: 16 | B25: 45714 | C25: A 8379 CO | D25: Pak Yoyok | E25: hiu | F25: bu kasmi madiun | G25: 10000 | H25: 1500000 | I25: tf | J25: 850000 | K25: cash | L25: =H25-J25 -> 650000 | M25: 600000
A26: 17 | B26: 45715 | C26: A 8379 CO | D26: Pak Yoyok | E26: panah | F26: p sukem ngawi | G26: 10000 | H26: 1500000 | I26: tf | J26: 950000 | K26: cash | L26: =H26-J26 -> 550000
A27: 18 | B27: 45716 | C27: A 8379 CO | D27: Pak Yoyok | E27: selendang, lotus | F27: p roni malang | G27: 9000 | H27: 1200000 | I27: cash | J27: 665000 | K27: cash | L27: =H27-J27 -> 535000
L28: =SUM(L10:L27) -> 10090000 | M28: =SUM(M10:M27) -> 7481000
L29: =L28-M28 -> 2609000
M30: .
A31: NO | B31: TANGGAL | C31: NO. POL | D31: DRIVER | E31: MERK KEDELAI | F31: PENERIMA | G31: BERAT (kg) | H31: ONGKOSAN | I31: KET | J31: SAKU SOPIR | K31: KET | L31: SETORAN | M31: KERUSAKAN
A32: 1 | B32: 45719 | C32: A 8379 CO | D32: Pak Yoyok | E32: lotus | F32: p ramin ngawi | G32: 10000 | H32: 1600000 | I32: tf | J32: 950000 | K32: cash | L32: =H32-J32 -> 650000
A33: 2 | B33: 45720 | C33: A 8379 CO | D33: Pak Yoyok | E33: panah | F33: p sukem ngawi | G33: 10000 | H33: 1500000 | I33: tf | J33: 950000 | K33: cash | L33: =H33-J33 -> 550000
A34: 3 | B34: 45722 | C34: A 8379 CO | D34: Pak Yoyok | E34: panah | F34: bu eni tulangan | G34: 9000 | H34: 800000 | I34: cash | J34: 400000 | K34: cash | L34: =H34-J34 -> 400000 | M34: 1356500
A35: 4 | B35: 45724 | C35: A 8379 CO | D35: Pak Yoyok | E35: hiu | F35: p mul surabaya | G35: 10000 | H35: 800000 | I35: tf | J35: 425000 | K35: cash | L35: =H35-J35 -> 375000
A36: 5 | B36: 45726 | C36: A 8379 CO | D36: Pak Yoyok | E36: hiu | F36: bu kasmi madiun | G36: 10000 | H36: 1500000 | I36: tf | J36: 850000 | K36: cash | L36: =H36-J36 -> 650000
A37: 6 | B37: 45727 | C37: A 8379 CO | D37: Pak Yoyok | E37: hiu | F37: bu kasmi madiun | G37: 10000 | H37: 1500000 | I37: tf | J37: 850000 | K37: tf | L37: =H37-J37 -> 650000 | M37: 65000
A38: 7 | B38: 45729 | C38: A 8379 CO | D38: Pak Yoyok | E38: panah | F38: abah ran madiun | G38: 10000 | H38: 1500000 | I38: tf | J38: 850000 | K38: cash | L38: =H38-J38 -> 650000
A39: 8 | B39: 45731 | C39: A 8379 CO | D39: Pak Yoyok | E39: panah | F39: p sukem ngawi | G39: 10000 | H39: 1500000 | I39: tf | J39: 950000 | K39: cash | L39: =H39-J39 -> 550000
A40: 9 | B40: 45733 | C40: A 8379 CO | D40: Pak Yoyok | E40: hiu | F40: bu kasmi madiun | G40: 10000 | H40: 1500000 | I40: tf | J40: 850000 | K40: cash | L40: =H40-J40 -> 650000
A41: 10 | B41: 45734 | C41: A 8379 CO | D41: Pak Yoyok | E41: hiu | F41: bu kasmi madiun | G41: 10000 | H41: 1500000 | I41: tf | J41: 850000 | K41: cash | L41: =H41-J41 -> 650000
A42: 11 | B42: 45735 | C42: A 8379 CO | D42: Pak Yoyok | E42: panah | F42: bu nur kopti mojokerto | G42: 9000 | H42: 765000 | I42: tf | J42: 450000 | K42: cash | L42: =H42-J42 -> 315000 | M42: 105000
...

Sheet P DWI (K 8094 IS)
A2: NO | B2: TANGGAL | C2: NO. POL | D2: DRIVER | E2: MERK KEDELAI | F2: PENERIMA | G2: BERAT (kg) | H2: ONGKOSAN | I2: KET | J2: SAKU SOPIR | K2: KET | L2: SETORAN | M2: KERUSAKAN
A3: 1 | B3: 45842 | C3: K 8094 IS | D3: M Ilham | E3: lotus | F3: toko putra bumi berkah | G3: 9000 | H3: 675000 | I3: cash | J3: 350000 | K3: cash | L3: =H3-J3 -> 325000 | M3: 7895000
A4: 2 | B4: 45843 | C4: K 8094 IS | D4: P Dwi | E4: pakan ternak | F4: ADM kediri | G4: 7000 | H4: 1550003 | I4: tf | J4: 640000 | K4: tf | L4: =H4-J4 -> 910003
A5: 3 | B5: 45845 | C5: K 8094 IS | D5: P Dwi | E5: pakan ternak | F5: ADM kediri | G5: 7000 | H5: 1550003 | I5: tf | J5: 640000 | K5: tf | L5: =H5-J5 -> 910003
A6: 4 | B6: 45846 | C6: K 8094 IS | D6: P Dwi | E6: pakan ternak | F6: ADM kediri | G6: 6250 | H6: 1550003 | I6: tf | J6: 640000 | K6: tf | L6: =H6-J6 -> 910003
A7: 5 | B7: 45847 | C7: K 8094 IS | D7: P Dwi | E7: pakan ternak | F7: ADM kediri | G7: 4500 | H7: 1550003 | I7: tf | J7: 640000 | K7: tf | L7: =H7-J7 -> 910003
A8: 6 | B8: 45849 | C8: K 8094 IS | D8: P Dwi | E8: pakan ternak | F8: ADM blitar | G8: 5300 | H8: 1550003 | I8: tf | J8: 750000 | K8: tf | L8: =H8-J8 -> 800003
A9: 7 | B9: 45850 | C9: K 8094 IS | D9: P Dwi | E9: TMM | F9: toko bumi berkah blitar | G9: 9000 | H9: 1350000 | I9: tf | J9: 850000 | K9: tf | L9: =H9-J9 -> 500000
A10: 8 | B10: 45852 | C10: K 8094 IS | D10: P Dwi | E10: pakan ternak | F10: ADM malang | G10: 8000 | H10: 1771432 | I10: tf | J10: 800000 | K10: tf | L10: =H10-J10 -> 971432
A11: 9 | B11: 45853 | C11: K 8094 IS | D11: P Dwi | E11: panah | F11: pak anwar porong | G11: 6000 | H11: 600000 | I11: cash | J11: 350000 | K11: tf | L11: =H11-J11 -> 250000
A12: 10 | B12: 45854 | C12: K 8094 IS | D12: P Dwi | E12: pakan ternak | F12: ADM kediri | G12: 6000 | H12: 1550003 | I12: tf | J12: 640000 | K12: tf | L12: =H12-J12 -> 910003 | M12: 133000
A13: 11 | B13: 45855 | C13: K 8094 IS | D13: P Dwi | E13: lotus | F13: pak yoyok jombang | G13: 10000 | H13: 1100000 | I13: tf | J13: 600000 | K13: tf | L13: =H13-J13 -> 500000
A14: 12 | B14: 45857 | C14: K 8094 IS | D14: P Dwi | E14: sip | F14: abah mif gresik | G14: 9000 | H14: 720000 | I14: tf | J14: 375000 | K14: tf | L14: =H14-J14 -> 345000
A15: 13 | B15: 45859 | C15: K 8094 IS | D15: P Dwi | E15: panah | F15: pak yoyok jombang | G15: 10000 | H15: 1100000 | I15: tf | J15: 600000 | K15: tf | L15: =H15-J15 -> 500000
A16: 14 | B16: 45860 | C16: K 8094 IS | D16: P Dwi | E16: pakan ternak | F16: ADM kediri | G16: 6500 | H16: 1550003 | I16: tf | J16: 700000 | K16: cash | L16: =H16-J16 -> 850003
A17: 15 | B17: 45861 | C17: K 8094 IS | D17: P Dwi | E17: hiu | F17: bu eni tulangan | G17: 9000 | H17: 800000 | I17: cash | J17: 400000 | K17: tf | L17: =H17-J17 -> 400000
A18: 16 | B18: 45863 | C18: K 8094 IS | D18: P Dwi | E18: selendang | F18: pak roni, toko bumi berkah blitar | G18: 9000 | H18: 1914000 | I18: cash+tf | J18: 850000 | K18: tf | L18: =H18-J18 -> 1064000 | M18: 458000 | N18: 564000
A19: 17 | B19: 45864 | C19: K 8094 IS | D19: P Dwi | E19: selendang | F19: pak yoyok jombang | G19: 10000 | H19: 1100000 | I19: tf | J19: 600000 | K19: tf | L19: =H19-J19 -> 500000
A20: 18 | B20: 45866 | C20: K 8094 IS | D20: P Dwi | E20: pakan ternak | F20: ADM ponorogo | G20: 7000 | H20: 1550003 | I20: tf | J20: 900000 | K20: tf | L20: =H20-J20 -> 650003 | M20: 728000
A21: 19 | B21: 45868 | C21: K 8094 IS | D21: P Dwi | E21: sip | F21: toko bumi berkah blitar | G21: 9000 | H21: 1350000 | I21: tf | J21: 875000 | K21: cash | L21: =H21-J21 -> 475000 | M21: 6290000
A22: 20 | B22: 45869 | C22: K 8094 IS | D22: P Dwi | E22: selendang | F22: abah slamet tobo | G22: 9000 | H22: 1215000 | I22: tf | J22: 700000 | K22: tf | L22: =H22-J22 -> 515000
L23: =SUM(L3:L21) -> 12680456 | M23: =SUM(M3:M21) -> 15504000
L24: =L23-M23 -> -2823544
A26: NO | B26: TANGGAL | C26: NO. POL | D26: DRIVER | E26: MERK KEDELAI | F26: PENERIMA | G26: BERAT (kg) | H26: ONGKOSAN | I26: KET | J26: SAKU SOPIR | K26: KET | L26: SETORAN | M26: KERUSAKAN
A27: 1 | B27: 45870 | C27: K 8094 IS | D27: P Dwi | E27: sip | F27: abah rohmat kediri | G27: 9000 | H27: 1200000 | I27: cash | J27: 690000 | K27: tf | L27: =H27-J27 -> 510000 | M27: 700000
A28: 2 | B28: 45873 | C28: K 8094 IS | D28: P Dwi | E28: selendang | F28: pak yoyok jombang | G28: 10000 | H28: 1100000 | I28: tf | J28: 600000 | K28: cash | L28: =H28-J28 -> 500000
A29: 3 | B29: 45874 | C29: K 8094 IS | D29: P Dwi | E29: selendang | F29: pak yoyok jombang | G29: 10000 | H29: 1100000 | I29: tf | J29: 600000 | K29: cash | L29: =H29-J29 -> 500000
A30: 4 | B30: 45875 | C30: K 8094 IS | D30: P Dwi | E30: TMM | F30: pak yanto porong | G30: 10000 | H30: 1000000 | I30: tf | J30: 475000 | K30: tf | L30: =H30-J30 -> 525000 | M30: 322000
A31: 5 | B31: 45876 | C31: K 8094 IS | D31: P Dwi | E31: sip | F31: bu iin sepanjang | G31: 9000 | H31: 675000 | I31: tf | J31: 400000 | K31: tf | L31: =H31-J31 -> 275000
A32: 6 | B32: 45878 | C32: K 8094 IS | D32: P Dwi | E32: selendang | F32: pak yoyok jombang | G32: 10000 | H32: 1100000 | I32: tf | J32: 600000 | K32: tf | L32: =H32-J32 -> 500000
A33: 7 | B33: 45880 | C33: K 8094 IS | D33: P Dwi | E33: BW | F33: pak ridwan manyar | G33: 9000 | H33: 720000 | I33: cash | J33: 350000 | K33: tf | L33: =H33-J33 -> 370000
A34: 8 | B34: 45880 | C34: K 8094 IS | D34: P Dwi | E34: prama | F34: toko putra bumi berkah | G34: 9000 | H34: 675000 | I34: cash | J34: 350000 | K34: tf | L34: =H34-J34 -> 325000
A35: 9 | B35: 45881 | C35: K 8094 IS | D35: P Dwi | E35: sip | F35: abah zakaria jombang | G35: 10000 | H35: 1100000 | I35: tf | J35: 625000 | K35: tf | L35: =H35-J35 -> 475000
A36: 10 | B36: 45882 | C36: K 8094 IS | D36: P Dwi | E36: sip | F36: bu yatini ngawi | G36: 9000 | H36: 1350000 | I36: tf | J36: 925000 | K36: tf | L36: =H36-J36 -> 425000
A37: 11 | B37: 45883 | C37: K 8094 IS | D37: P Dwi | E37: sip | F37: toko bumi berkah blitar | G37: 9000 | H37: 1350000 | J37: 875000 | K37: tf | L37: =H37-J37 -> 475000
A38: 12 | B38: 45884 | C38: K 8094 IS | D38: P Dwi | E38: pakan | F38: ADM malang kesambon | G38: 8000 | H38: 1771432 | J38: 640000 | K38: tf | L38: =H38-J38 -> 1131432
A39: 13 | B39: 45885 | C39: K 8094 IS | D39: P Dwi | E39: selendang | F39: pak yoyok jombang | G39: 10000 | H39: 1100000 | I39: tf | J39: 600000 | K39: tf | L39: =H39-J39 -> 500000 | M39: 293000
A40: 14 | B40: 45887 | C40: K 8094 IS | D40: P Dwi | E40: sip | F40: pak ridwan manyar | G40: 9000 | H40: 720000 | I40: cash | J40: 375000 | K40: tf | L40: =H40-J40 -> 345000
A41: 15 | B41: 45888 | C41: K 8094 IS | D41: P Dwi | E41: BW | F41: bu tutik sumberejo | G41: 9000 | H41: 990000 | J41: 550000 | K41: tf | L41: =H41-J41 -> 440000 | M41: 329000
A42: 16 | B42: 45889 | C42: K 8094 IS | D42: P Dwi | E42: hiu | F42: pak mul surabaya | G42: 8000 | H42: 800000 | I42: tf | J42: 375000 | K42: tf | L42: =H42-J42 -> 425000
...

Sheet P AGIK (S 8903 UX)
B1: TANGGAL | C1: NO. POL | D1: DRIVER | E1: MERK KEDELAI | F1: PENERIMA | G1: BERAT (kg) | H1: ONGKOSAN | I1: KET | J1: SAKU SOPIR | K1: KET | L1: SETORAN | M1: KERUSAKAN
B2: 45593 | C2: W 8882 DS | D2: Pak Firman | E2: Lotus | F2: Toko Putra Bumi Berkah | G2: 10000 | H2: 750000 | I2: Cash | J2: 100000 | K2: Cash | L2: =H2-J2 -> 650000
L3: =SUM(L2) -> 650000 | M3: =SUM(M2) -> 0
L4: =L3-M3 -> 650000
A6: NO | B6: TANGGAL | C6: NO. POL | D6: DRIVER | E6: MERK KEDELAI | F6: PENERIMA | G6: BERAT (kg) | H6: ONGKOSAN | I6: KET | J6: SAKU SOPIR | K6: KET | L6: SETORAN | M6: KERUSAKAN
A7: 1 | B7: 45607 | C7: W 8882 DS | D7: Pak Hendro | E7: Hiu | F7: Mas nanang Bojonegoro | G7: 8000 | H7: 1200000 | I7: TF | J7: 640000 | K7: cash | L7: =H7-J7 -> 560000 | M7: 1405000
A8: 2 | B8: 45608 | C8: W 8882 DS | D8: Pak Hendro | E8: Panah | F8: Bu Tutik Bojonegoro (Toko) | G8: 9000 | H8: 1125000 | I8: Cash | J8: 640000 | K8: cash | L8: =H8-J8 -> 485000 | M8: 32000
A9: 3 | B9: 45609 | C9: W 8882 DS | D9: Pak Hendro | E9: Jempol Sip | F9: Toko Roni Sederhana Malang | G9: 8500 | H9: 1200000 | I9: Cash | J9: 640000 | K9: cash | L9: =H9-J9 -> 560000 | M9: 95000
A10: 4 | B10: 45611 | C10: W 8882 DS | D10: Pak Hendro | E10: Hiu | F10: Bu Kasmi MAdiun | G10: 10000 | H10: 1500000 | I10: TF | J10: 850000 | K10: cash | L10: =H10-J10 -> 650000
A11: 5 | B11: 45614 | C11: W 8882 DS | D11: Pak Hendro | E11: Hiu | F11: Bu Kasmi MAdiun | G11: 10000 | H11: 1500000 | I11: TF | J11: 850000 | K11: cash | L11: =H11-J11 -> 650000
A12: 6 | B12: 45615 | C12: W 8882 DS | D12: Pak Hendro | E12: Panah | F12: Mba Tiwuk nganjuk | G12: 9000 | H12: 1170000 | I12: Cash | J12: 640000 | K12: TF | L12: =H12-J12 -> 530000
A13: 7 | B13: 45617 | C13: W 8882 DS | D13: Pak Hendro | E13: Lotus | F13: Pak Saiku Malang | G13: 9000 | H13: 1305000 | I13: TF | J13: 725000 | K13: cash | L13: =H13-J13 -> 580000
A14: 8 | B14: 45618 | C14: W 8882 DS | D14: Pak Hendro | E14: Panah | F14: Bu Tutik Bojonegoro (Toko) | G14: 9000 | H14: 1125000 | I14: Cash | J14: 640000 | K14: TF | L14: =H14-J14 -> 485000
A15: 9 | B15: 45619 | C15: W 8882 DS | D15: Pak Hendro | E15: Panah | F15: Abah Muh Madura | G15: 9000 | H15: 1400000 | I15: TF | J15: 850000 | K15: cash | L15: =H15-J15 -> 550000
A16: 10 | B16: 45621 | C16: W 8882 DS | D16: Pak Hendro | E16: Jempol Sip | F16: Pak Ramin Ngawi | G16: 10000 | H16: 1600000 | I16: TF | J16: 975000 | K16: cash | L16: =H16-J16 -> 625000
A17: 11 | B17: 45622 | C17: W 8882 DS | D17: Pak Hendro | E17: Hiu | F17: Toko Putra bumi berkah | G17: 10000 | H17: 750000 | I17: Cash | J17: 375000 | K17: TF | L17: =H17-J17 -> 375000 | M17: 100000
A18: 12 | B18: 45624 | C18: W 8882 DS | D18: Pak Hendro | E18: Panah | F18: Abah Muh Madura | G18: 9000 | H18: 1400000 | I18: TF | J18: 850000 | K18: TF | L18: =H18-J18 -> 550000
A19: 13 | B19: 45625 | C19: W 8882 DS | D19: Pak Hendro | E19: Lotus | F19: Abah parnoto blitar | G19: 9000 | H19: 1350000 | I19: Cash | J19: 875000 | K19: cash | L19: =H19-J19 -> 475000
L20: =SUM(L7:L19) -> 7075000 | M20: =SUM(M7:M19) -> 1632000
L21: =L20-M20 -> 5443000
A23: NO | B23: TANGGAL | C23: NO. POL | D23: DRIVER | E23: MERK KEDELAI | F23: PENERIMA | G23: BERAT (kg) | H23: ONGKOSAN | I23: KET | J23: SAKU SOPIR | K23: KET | L23: SETORAN | M23: KERUSAKAN
A24: 1 | B24: 45628 | C24: W 8882 DS | D24: Pak Hendro | E24: jempol sip | F24: Abah slamet tobo | G24: 9000 | H24: 1215000 | I24: TF | J24: 725000 | K24: Cash | L24: =H24-J24 -> 490000
A25: 2 | B25: 45629 | C25: W 8882 DS | D25: Pak Hendro | E25: Hiu | F25: Abah mif | G25: 9000 | H25: 900000 | I25: TF | J25: 350000 | K25: Cash | L25: =H25-J25 -> 550000
A26: 3 | B26: 45630 | C26: W 8882 DS | D26: Pak Hendro | E26: Hiu | F26: Bu Kasmi Madiun | G26: 10000 | H26: 1500000 | I26: TF | J26: 850000 | K26: Cash+TF | L26: =H26-J26 -> 650000
