Workbook

Sheet Jan
A1: CV PUTRA BUMI BERKAH
A2: NERACA
A3: 45657
F5: Selisih = | G5: 11449609
D6: Saldo
A7: Aset | D7: IDR | F7: Rincian =
B8: Bank | F8: Pemasukan
C9: 123-0467834 (BCA) | D9: 1.6805354e+08 | F9: laba tgl 31 | G9: 15900000
C10: 735-5917878 (BCA) | D10: 40420364 | F10: bunga rek 7834 | G10: 2028.32
C11: 735-5537889 (BCA) | D11: -2.7346707e+08 | F11: bunga rek 7878 | G11: 608.11
C12: 735-5467899 (BCA) | D12: 2639027 | F12: revisi harga pak arif tgl 30/12 | G12: 2800000
C13: 620801016258532 (BRI) | D13: 10023500 | G13: =SUM(G9:G12) -> 18702636
C14: 058301001067560 (BRI) | D14: 1.1654253e+08 | F14: Pengeluaran
C15: 058301900009562 (BRI) | D15: 321076645 | F15: BI-Fast cv pbb | G15: 2500
C16: 058301909090560 (BRI) | D16: 130317 | F16: bagi hasil pak itak | G16: 5000000
B17: Total Bank | D17: =SUM(D9:D16) -> 3.8541885e+08 | F17: bagi hasil bu tutik | G17: 2250000
F18: pajak bunga rek 7834 | G18: 405.66
B19: Piutang | F19: pajak bunga rek 7878 | G19: 121.62
C20: Customer | D20: 2362409940 | G20: =SUM(G15:G19) -> 7253027.3
C21: Customer ragi | D21: 51770000
C22: Toko putra bumi berkah | D22: 778056500 | F22: Pemasukan - pengeluaran | G22: =G13-G20 -> 11449609
C23: Pak nanok | D23: 25000000
C24: Pak ozi (blitar) | D24: 30000000
C25: Beli aset tanah | D25: 141000000
C26: Beli aset tanah | D26: 145000000
D27: =SUM(D20:D26) -> 3533236440
B29: Ragi
C30: Ragi 180x602500 | D30: 108450000
C31: Ragi 13x602500 | D31: 7832500
D32: =SUM(D30:D31) -> 116282500
B34: Deposit
C35: SGR 9000x8000 | D35: 72000000
D36: =D35 -> 72000000
A38: Hutang
C39: PT Agrico International | D39: 1409300000
C40: PT JPM-ADM Indonesia | D40: 1735392980
C41: PT Terus Makmur Mandiri | D41: 131200000
D42: =SUM(D39:D41) -> 3275892980
A44: Total aset + Piutang - Hutang | D44: =D17+D27+D32+D36-D42 -> 8.3104481e+08
A47: CV PUTRA BUMI BERKAH
...

Sheet Feb
A1: CV PUTRA BUMI BERKAH
A2: NERACA
A3: 45689
F5: Selisih = | G5: =D47-Jan!D1190 -> -31217414
D6: Saldo
A7: Aset | D7: IDR | F7: Rincian =
B8: Bank | F8: Pemasukan
C9: 123-0467834 (BCA) | D9: 6257030.5 | F9: laba tgl 1 | G9: 16119000
C10: 735-5917878 (BCA) | D10: 74416200 | F10: laba ragi | G10: 190000
C11: 735-5537889 (BCA) | D11: 1.9027659e+08 | F11: bunga individu 7834 | G11: 1562.42
C12: 735-5467899 (BCA) | D12: 3361961 | F12: bunga individu 7878 | G12: 1045.54
C13: 620801016258532 (BRI) | D13: 10885100 | G13: =SUM(G9:G12) -> 16311608
C14: 058301001067560 (BRI) | D14: 29627287 | F14: Pengeluaran
C15: 058301900009562 (BRI) | D15: 120552779 | F15: BI-Fast bri bisnis | G15: 2500
C16: 058301909090560 (BRI) | D16: 130317 | F16: pot harga ko hadi | G16: 900000
B17: Total Bank | D17: =SUM(D9:D16) -> 4.3550727e+08 | F17: bayar BFI & BRI an bayu adi angs ke 14 | G17: 13478500
F18: buka kas | G18: 5000000
B19: Piutang | F19: gaji karyawan januari 2025 | G19: 27700000
C20: Customer | D20: 2716182774 | F20: biaya ADM cv pbb & cv spbb | G20: 60000
C21: Customer ragi | D21: 7680000 | F21: BI-Fast cv pbb | G21: 12500
C22: Toko putra bumi berkah | D22: 902179500 | F22: pajak bunga individu 7834 | G22: 312.48
C23: Pak nanok | D23: 25000000 | F23: pajak bunga individu 7878 | G23: 209.11
C24: Pak ozi (blitar) | D24: 30000000 | F24: selisih harga panah | G24: 375000
C25: Beli aset tanah | D25: 141000000 | G25: =SUM(G15:G24) -> 47529022
C26: Beli aset tanah | D26: 145000000
C27: Pak deny pinjam | D27: 100000000 | F27: Pemasukan - pengeluaran | G27: =G13-G25 -> -31217414
D28: =SUM(D20:D27) -> 4067042274
B30: Ragi
C31: Ragi 46x602500 | D31: 27715000
C32: Ragi 5x602500 | D32: 3012500
D33: =SUM(D31:D32) -> 30727500
B35: Deposit
C36: Tulip 4500x8300 | D36: 37350000
D37: =SUM(D36:D36) -> 37350000
A39: Hutang
C40: PT Agrico International | D40: 1231150000
C41: PT JPM-ADM Indonesia | D41: 1580182000
C42: PT Terus Makmur Mandiri | D42: 206400000
C43: Bu tutik tomat 9000x8450 | D43: 76050000
C44: Cv Maju Terus | D44: 401850000
...

Sheet Mar
A1: CV PUTRA BUMI BERKAH
A2: NERACA
A3: 45717
F5: Selisih = | G5: =D41-Feb!D1095 -> -34271387
D6: Saldo
A7: Aset | D7: IDR | F7: Rincian =
B8: Bank | F8: Pemasukan
C9: 123-0467834 (BCA) | D9: 78922776 | F9: laba tgl 1 | G9: 8954000
C10: 735-5917878 (BCA) | D10: 95869492 | F10: bu iin bayar lebih timbang tgl 27/2 20x8450 | G10: 169000
C11: 735-5537889 (BCA) | D11: 3.7509458e+08 | F11: bunga rek individu 7834 | G11: 1025.73
C12: 735-5467899 (BCA) | D12: 1054271 | F12: bunga rek individu 7878 | G12: 990.29
C13: 620801016258532 (BRI) | D13: 745200 | G13: =SUM(G9:G12) -> 9125016
C14: 058301001067560 (BRI) | D14: 89648393 | F14: Pengeluaran
C15: 058301900009562 (BRI) | D15: 544812211 | F15: BI-Fast cv pbb | G15: 7500
C16: 058301909090560 (BRI) | D16: 130317 | F16: gaji karyawan februari 25 | G16: 29850000
B17: Total Bank | D17: =SUM(D9:D16) -> 1.1862772e+09 | F17: bayar BFI & BRI an bayu adi angs ke 15 | G17: 13478500
F18: biaya ADM cv pbb & cv spbb | G18: 60000
B19: Piutang | F19: pajak bunga rek individu 7834 | G19: 205.15
C20: Customer | D20: 2793000024 | F20: pajak bunga rek individu 7878 | G20: 198.06
C21: Customer ragi | D21: 60180000 | G21: =SUM(G15:G20) -> 43396403
C22: Toko putra bumi berkah | D22: 814867500
C23: Pak nanok | D23: 25000000 | F23: Pemasukan - pengeluaran | G23: =G13-G21 -> -34271387
C24: Pak ozi (blitar) | D24: 30000000
C25: Beli aset tanah | D25: 141000000
C26: Beli aset tanah | D26: 145000000
C27: Uang cash mas hery | D27: 800000
C28: Dp terop | D28: 10000000
D29: =SUM(D20:D28) -> 4019847524
B31: Ragi
C32: Ragi 106x602500 | D32: 63865000
D33: =D32 -> 63865000
A35: Hutang
C36: PT Agrico International | D36: 2674525000
C37: PT JPM-ADM Indonesia | D37: 1639657500
C38: PT Terus Makmur Mandiri | D38: 75150000
D39: =SUM(D36:D38) -> 4389332500
A41: Total aset + Piutang - Hutang | D41: =D17+D29+D33-D39 -> 8.8065727e+08
A44: CV PUTRA BUMI BERKAH
A45: NERACA
A46: 45719
...

Sheet Apr
A1: CV PUTRA BUMI BERKAH
A2: NERACA
A3: 45749
F5: Selisih = | G5: =D44-Mar!D1111 -> -5949871.7
D6: Saldo
A7: Aset | D7: IDR | F7: Rincian =
B8: Bank | F8: Pemasukan
C9: 123-0467834 (BCA) | D9: 1.0642059e+08 | F9: laba tgl 2 | G9: 0
C10: 735-5917878 (BCA) | D10: 80129954 | F10: bunga indv 7834 | G10: 833.54
C11: 735-5537889 (BCA) | D11: -1.7949134e+08 | F11: bunga indv 7878 | G11: 576.87
C12: 735-5467899 (BCA) | D12: 342589581 | G12: =SUM(G9:G11) -> 1410.41
C13: 620801016258532 (BRI) | D13: 1605300 | F13: Pengeluaran
C14: 058301001067560 (BRI) | D14: 12895893 | F14: biaya adm cv pbb & spbb | G14: 60000
C15: 058301900009562 (BRI) | D15: -75062562 | F15: DB-Otomatis kliring cv spbb | G15: 6000
C16: 058301909090560 (BRI) | D16: 130317 | F16: THR pak pendik sopir | G16: 1500000
B17: Total Bank | D17: =SUM(D9:D16) -> 2.8921773e+08 | F17: BI-Fast individu | G17: 5000
F18: pengeluaran lain2 | G18: 3380000
B19: Piutang | F19: tambahan THR pak mantri | G19: 1000000
C20: Customer | D20: 2056893450 | F20: pajak bunga indv 7834 | G20: 166.71
C21: Customer ragi | D21: 5890000 | F21: pajak bunga indv 7878 | G21: 115.37
C22: Toko putra bumi berkah | D22: 828493500 | G22: =SUM(G14:G21) -> 5951282.1
C23: Pak nanok | D23: 25000000
C24: Pak ozi (blitar) | D24: 30000000 | F24: Pemasukan - pengeluaran | G24: =G12-G22 -> -5949871.7
C25: Beli aset tanah | D25: 141000000
C26: Beli aset tanah | D26: 145000000
C27: Tukar uang baru | D27: 17000000
C28: Beli truk W 8707 DQ | D28: 160000000
C29: Dp terop | D29: 10000000
D30: =SUM(D20:D29) -> 3419276950
B32: Ragi
C33: Ragi 243x602500 | D33: 146407500
C34: Ragi 2x602500 | D34: 1205000
D35: =SUM(D33:D34) -> 147612500
A37: Hutang
C38: PT Agrico International | D38: 884500000
C39: PT JPM-ADM Indonesia | D39: 1884861500
C40: PT Terus Makmur Mandiri | D40: 313750000
C41: TSC ko tejo 9000x8300 | D41: 74700000
D42: =SUM(D38:D41) -> 3157811500
A44: Total aset + Piutang - Hutang | D44: =D17+D30+D35-D42 -> 6.9829568e+08
...

Sheet Mei
A1: CV PUTRA BUMI BERKAH
A2: NERACA
A3: 45779
F5: Selisih = | G5: =D44-Apr!D1172 -> 10101099
D6: Saldo
A7: Aset | D7: IDR | F7: Rincian =
B8: Bank | F8: Pemasukan
C9: 123-0467834 (BCA) | D9: 3213468.8 | F9: laba tgl 2 + 3 | G9: 28347000
C10: 735-5917878 (BCA) | D10: 1.6505014e+08 | F10: laba ragi | G10: 135000
C11: 735-5537889 (BCA) | D11: -4.1276642e+08 | F11: pak yoyok bayar lebih timbang tgl 30/4 | G11: 191000
C12: 735-5467899 (BCA) | D12: 237896 | F12: bunga rek 7878 | G12: 861.44
C13: 620801016258532 (BRI) | D13: 24250 | F13: bunga rek 7834 | G13: 1099.82
C14: 058301001067560 (BRI) | D14: 1.1400357e+08 | G14: =SUM(G9:G13) -> 28674961
C15: 058301900009562 (BRI) | D15: -135705867 | F15: Pengeluaran
C16: 058301909090560 (BRI) | D16: 130317 | F16: biaya adm cv spbb & pbb | G16: 60000
B17: Total Bank | D17: =SUM(D9:D16) -> -2.6581264e+08 | F17: RTGS bri bisnis | G17: 30000
F18: bayar BFI & BRI an bayu adi angs ke 17 | G18: 13478500
B19: Piutang | F19: biaya kliring | G19: 2000
C20: Customer | D20: 2875016525 | F20: pajak bunga rek 7878 | G20: 172.29
C21: Customer ragi | D21: 6400000 | F21: pajak bunga rek 7834 | G21: 219.96
C22: Toko putra bumi berkah | D22: 792234500 | F22: qris terpotong | G22: 2970
C23: Pak nanok | D23: 25000000 | F23: buka kas | G23: 5000000
C24: Pak ozi (blitar) | D24: 30000000 | G24: =SUM(G16:G23) -> 18573862
C25: Beli aset tanah | D25: 141000000
C26: Beli aset tanah | D26: 145000000 | F26: Pemasukan - pengeluaran | G26: =G14-G24 -> 10101099
C27: Pak budi pinjam | D27: 55000000
C28: Deposit PT Terus Makmur Mandiri | D28: 94500000
C29: Stock BW di gudang | D29: 79650000
C30: Uang cash mas heri | D30: 1660000
D31: =SUM(D20:D30) -> 4245461025
B33: Ragi
C34: Ragi 121x602500 | D34: 72902500
C35: Ragi 5x602500 | D35: 3012500
D36: =SUM(D34:D35) -> 75915000
A38: Hutang
C39: PT Agrico International | D39: 1216700000
C40: PT JPM-ADM Indonesia | D40: 1420726000
C41: DO bw bu tutik | D41: 14250000
D42: =SUM(D39:D41) -> 2651676000
A44: Total aset + Piutang - Hutang | D44: =D17+D31+D36-D42 -> 1.4038874e+09
...

Sheet Juni
A1: CV PUTRA BUMI BERKAH
A2: NERACA
A3: 45810
F5: Selisih = | G5: =D44-Mei!D1107 -> -18900970
D6: Saldo
A7: Aset | D7: IDR | F7: Rincian =
B8: Bank | F8: Pemasukan
C9: 123-0467834 (BCA) | D9: 1.1110809e+08 | F9: laba tgl 2 | G9: 2922000
C10: 735-5917878 (BCA) | D10: 39938299 | F10: laba ragi | G10: 375000
C11: 735-5537889 (BCA) | D11: 4.0663301e+08 | F11: bunga rek indv 7878 | G11: 819.33
C12: 735-5467899 (BCA) | D12: 90506 | F12: bunga rek indv 7834 | G12: 1093.42
C13: 620801016258532 (BRI) | D13: 16250 | G13: =SUM(G9:G12) -> 3298912.8
C14: 058301001067560 (BRI) | D14: 1.4991665e+08 | F14: Pengeluaran
C15: 058301900009562 (BRI) | D15: -42077063 | F15: adm kliring cv surya | G15: 6000
C16: 058301909090560 (BRI) | D16: 130317 | F16: biaya adm cv spbb + cv pbb | G16: 60000
B17: Total Bank | D17: =SUM(D9:D16) -> 6.6575606e+08 | F17: pajak bunga rek indv 7878 | G17: 163.87
F18: pajak bunga rek indv 7834 | G18: 218.68
B19: Piutang | F19: BI-Fast bri bisnis | G19: 5000
C20: Customer | D20: 3238321505 | F20: angs bri unit ke 1 an bayu adi | G20: 14550000
C21: Customer ragi | D21: 12355000 | F21: angs BFI ke 18 an bayu adi | G21: 7578500
C22: Toko putra bumi berkah | D22: 957417500 | G22: =SUM(G15:G21) -> 22199883
C23: Pak nanok | D23: 25000000
C24: Pak ozi (blitar) | D24: 30000000 | F24: Pemasukan - pengeluaran | G24: =G13-G22 -> -18900970
C25: Beli aset tanah | D25: 141000000
C26: Beli aset tanah | D26: 145000000
C27: Pak budi pinjam | D27: 100000000
C28: Beli truk S 9344 ND + K 8094 IS | D28: 155002500
C29: Dp mobil fortuner | D29: 156395550
C30: Deposit di TMM | D30: 60125000
D31: =SUM(D20:D30) -> 5020617055
B33: Ragi
C34: Ragi 229x602500 | D34: =229*602500 -> 137972500
C35: Ragi 6x602500 | D35: =6*602500 -> 3615000
D36: =SUM(D34:D35) -> 141587500
A38: Hutang
C39: PT Agrico International | D39: 2301300000
C40: PT JPM-ADM Indonesia | D40: 1768305000
C41: Cv Maju Terus | D41: 174800000
D42: =SUM(D39:D41) -> 4244405000
A44: Total aset + Piutang - Hutang | D44: =D17+D31+D36-D42 -> 1.5835556e+09
...

Sheet Juli
A1: CV PUTRA BUMI BERKAH
A2: NERACA
A3: 45839
F5: Selisih = | G5: =D49-Juni!D1133 -> -1.0025335e+08
D6: Saldo
A7: Aset | D7: IDR | F7: Rincian =
B8: Bank | F8: Pemasukan
C9: 123-0467834 (BCA) | D9: 2.0009422e+08 | F9: laba tgl 1 | G9: -4966000
C10: 735-5917878 (BCA) | D10: 1.0885379e+08 | F10: bunga rek indv 7878 | G10: 610.67
C11: 735-5537889 (BCA) | D11: 1.6046906e+08 | F11: bunga rek indv 7834 | G11: 1450.46
C12: 735-5467899 (BCA) | D12: 17952116 | G12: =SUM(G9:G11) -> -4963938.9
C13: 620801016258532 (BRI) | D13: 8250 | F13: Pengeluaran
C14: 058301001067560 (BRI) | D14: 894733.6 | F14: biaya adm kliring cv spbb | G14: 6000
C15: 058301900009562 (BRI) | D15: 14012245 | F15: biaya adm cv pbb & spbb | G15: 60000
C16: 058301909090560 (BRI) | D16: 130317 | F16: bagi hasil bu tutik | G16: 2250000
B17: Total Bank | D17: =SUM(D9:D16) -> 5.0241472e+08 | F17: BI-Fast cv pbb | G17: 10000
F18: gaji karyawan bulan juni 2025 | G18: 30350000
B19: Piutang | F19: angs bri unit ke 2 an bayu adi | G19: 14550000
C20: Customer | D20: 3246817605 | F20: angs BFI ke 19 an bayu adi | G20: 7578500
C21: Customer ragi | D21: 14000000 | F21: angs BFI ke 1 an suryo hadi | G21: 11503000
C22: Toko putra bumi berkah | D22: 872103000 | F22: angs TAF ke 1 an suryo hadi | G22: 23975000
C23: Toko putra bumi berkah blitar | D23: 219033000 | F23: biaya adm tf ke bank lain cv pbb | G23: 6500
C24: Pak nanok | D24: 25000000 | F24: pajak bunga rek indv 7878 | G24: 122.13
C25: Pak ozi (blitar) | D25: 30000000 | F25: pajak bunga rek indv 7834 | G25: 290.09
C26: Beli aset tanah | D26: 141000000 | F26: buka kas | G26: 5000000
C27: Beli aset tanah | D27: 145000000 | G27: =SUM(G14:G26) -> 95289412
C28: Pak budi pinjam | D28: 100000000
C29: Beli truk S 9344 ND + K 8094 IS | D29: 180880000 | F29: Pemasukan - pengeluaran | G29: =G12-G27 -> -1.0025335e+08
C30: Dp mobil fortuner | D30: 156395550
C31: Pembayaran tanah | D31: 304750000
C32: Bapak pinjam dari rek bri 560 | D32: 1185745
C33: Angkutan pinjam bri 560 | D33: 1002500
C34: Angkutan pinjam rek ragi | D34: 15002500
C35: Deposit di TMM | D35: 60125000
D36: =SUM(D20:D35) -> 5512294900
B38: Ragi
C39: Ragi 59x602500 | D39: =59*602500 -> 35547500
C40: Ragi 1x602500 | D40: =1*602500 -> 602500
D41: =SUM(D39:D40) -> 36150000
A43: Hutang
...

Sheet Agust
A1: CV PUTRA BUMI BERKAH
A2: NERACA
A3: 45870
F5: Selisih = | G5: =D43-Juli!D1312 -> -77545351
D6: Saldo
A7: Aset | D7: IDR | F7: Rincian =
B8: Bank | F8: Pemasukan
C9: 123-0467834 (BCA) | D9: 1.0137291e+08 | F9: laba tgl 1 | G9: 2744000
C10: 735-5917878 (BCA) | D10: 1.6655227e+08 | F10: pak sukem bayar lebih timbang tgl 23/7 | G10: 178000
C11: 735-5537889 (BCA) | D11: 2.1582998e+08 | F11: bunga rek indv 7878 | G11: 1224.03
C12: 735-5467899 (BCA) | D12: 5993726 | F12: bunga rek indv 7834 | G12: 837.8
C13: 620801016258532 (BRI) | D13: 2450083.6 | G13: =SUM(G9:G12) -> 2924061.8
C14: 058301001067560 (BRI) | D14: 873247 | F14: Pengeluaran
C15: 058301900009562 (BRI) | D15: 376452126 | F15: gaji karyawan bulan juli 2025 | G15: 31350000
C16: 058301909090560 (BRI) | D16: 130317 | F16: BI-fast cv putra | G16: 7500
B17: Total Bank | D17: =SUM(D9:D16) -> 8.6965466e+08 | F17: biaya adm cv pbb & cv spbb | G17: 60000
F18: biaya kliring cv spbb | G18: 2000
B19: Piutang | F19: angs bri unit ke 3 an bayu adi | G19: 14550000
C20: Customer | D20: 2428442137 | F20: angs BFI ke 20 an bayu adi | G20: 7578500
C21: Customer ragi | D21: 13465000 | F21: angs BFI ke 2 an suryo hadi | G21: 11503000
C22: Toko putra bumi berkah | D22: 1035510838 | F22: angs trihamas ke 1 an suryo hadi | G22: 10418000
C23: Toko putra blitar | D23: 463050000 | F23: pajak bunga rek indv 7878 | G23: 244.81
C24: Pak nanok | D24: 25000000 | F24: pajak bunga rek indv 7834 | G24: 167.56
C25: Pak ozi (blitar) | D25: 30000000 | F25: buka kas | G25: 5000000
C26: Pak budi pinjam | D26: 50000000 | G26: =SUM(G15:G25) -> 80469412
C27: Angkutan pinjam bri 560 | D27: 1002500
C28: Angkutan pinjam rek ragi | D28: 50005000 | F28: Pemasukan - pengeluaran | G28: =G13-G26 -> -77545351
D29: =SUM(D20:D28) -> 4096475475
B31: Ragi
C32: Ragi 296x602500 | D32: =296*602500 -> 178340000
C33: Ragi 6x602500 | D33: =6*602500 -> 3615000
C34: Ragi 4x602500 | D34: =4*602500 -> 2410000
D35: =SUM(D32:D34) -> 184365000
A37: Hutang
C38: PT Agrico International | D38: 2182050000
C39: PT JPM-ADM Indonesia | D39: 1465749030
C40: Cv Maju Terus | D40: 227475000
D41: =SUM(D38:D40) -> 3875274030
A43: Total aset + Piutang - Hutang | D43: =D17+D29+D35-D41 -> 1.2752211e+09
A46: CV PUTRA BUMI BERKAH
...

Sheet Sept
A1: CV PUTRA BUMI BERKAH
A2: NERACA
A3: 45901
F5: Selisih = | G5: =D46-Agust!D1209 -> -19908122
D6: Saldo
A7: Aset | D7: IDR | F7: Rincian =
B8: Bank | F8: Pemasukan
C9: 123-0467834 (BCA) | D9: 1.0635299e+08 | F9: laba tgl 1 | G9: 18188000
C10: 735-5917878 (BCA) | D10: 37173580 | F10: laba ragi | G10: 252500
C11: 735-5537889 (BCA) | D11: 1.5958453e+08 | F11: bunga rek indv 7834 | G11: 983.57
C12: 735-5467899 (BCA) | D12: 224967511 | F12: bunga rek indv 7878 | G12: 1641.96
C13: 620801016258532 (BRI) | D13: 25000 | G13: =SUM(G9:G12) -> 18443126
C14: 058301001067560 (BRI) | D14: 17233024 | F14: Pengeluaran
C15: 058301900009562 (BRI) | D15: 315736929 | F15: BI-Fast bri 560 | G15: 2500
C16: 058301909090560 (BRI) | D16: 130317 | F16: gaji karyawan bulan agustus 2025 | G16: 36850000
B17: Total Bank | D17: =SUM(D9:D16) -> 8.6120389e+08 | F17: pajak bunga rek indv 7834 | G17: 196.71
F18: pajak bunga rek indv 7878 | G18: 328.39
B19: Piutang | F19: biaya adm rek cv spbb & pbb | G19: 60000
C20: Customer | D20: 2371714637 | F20: BI-Fast rek indv 7878 | G20: 5000
C21: Customer ragi | D21: 24705000 | F21: angs BRI bisnis ? | G21: 1229772
C22: Toko putra bumi berkah | D22: 910182838 | F22: revisi harga pak arif tgl 31/7 | G22: 114450
C23: Toko putra blitar | D23: 530100000 | F23: revisi harga pak arif tgl 13/8 | G23: 84000
C24: Pak nanok | D24: 25000000 | F24: BI-Fast cv pbb | G24: 2500
C25: Pak ozi (blitar) | D25: 30000000 | F25: BI-Fast bri bisnis | G25: 2500
C26: Pak budi pinjam | D26: 50000000 | G26: =SUM(G15:G25) -> 38351247
C27: Bayar kontrak blitar | D27: 33000000
C28: Beli truk pak hasan W 8358 NZ | D28: 180000000 | F28: Pemasukan - pengeluaran | G28: =G13-G26 -> -19908122
C29: Angkutan pinjam bri 560 | D29: 1002500
C30: Angkutan pinjam rek ragi | D30: 50005000
D31: =SUM(D20:D30) -> 4205709975
B33: Ragi
C34: Ragi 198x602500 | D34: =198*602500 -> 119295000
C35: Ragi 9x602500 | D35: =9*602500 -> 5422500
C36: Ragi 0x602500 | D36: 0
D37: =SUM(D34:D36) -> 124717500
A39: Hutang
C40: PT Agrico International | D40: 1963100000
C41: PT JPM-ADM Indonesia | D41: 1561401500
C42: PT Kabulinco Jaya | D42: 336000000
C43: PT Terus Makmur Mandiri | D43: 25200000
...

Sheet Deposit
A1: Rincian deposit
A3: Keterangan | B3: Customer | C3: Rekening | D3: Nominal | E3: Tgl masuk | F3: Tgl keluar
A4: deposit lotus 9000x7750 + ongkir | B4: Abah slamet | C4: BCA cv putra | D4: 70965000 | E4: 45643 | F4: 45644 | G4: bri 100jt + bca 113.345.000 17/12
A5: deposit lotus 9000x7750 + ongkir | B5: Abah slamet | C5: BCA cv putra | D5: 42380000 | E5: 45643 | F5: 45646
C6: BRI bisnis | D6: 28585000 | E6: 45643 | F6: 45646
A7: deposit sip 9000x7800 + ongkir | B7: Abah slamet | C7: BRI bisnis | D7: 71415000 | E7: 45643 | F7: 45659
A8: deposit lotus 9000x7500 | B8: Kopti giri | C8: BRI bisnis | D8: 50000000 | E8: 45644 | F8: 45659
C9: BRI bisnis | D9: 17500000 | E9: 45645
A10: hiu 9000x8200 | B10: Bu iin | C10: BCA cv putra | D10: 73800000 | E10: 45650 | F10: 45659
A11: hiu 9000x8200 | B11: Bu iin | C11: BCA cv putra | D11: 73800000 | E11: 45650 | F11: 45668
A12: hiu 9000x8200 | B12: Bu iin | C12: BCA cv putra | D12: 73800000 | E12: 45650 | F12: 45680
A13: hiu 9000x7900 | B13: Ko hadi pohjejer | C13: BCA cv putra | D13: 71100000 | E13: 45652 | F13: 45660
A14: bola 9000x8000 | B14: Ko hadi pohjejer | C14: BCA cv putra | D14: 72000000 | E14: 45652 | F14: 45665
A15: deposit | B15: ATM | C15: BRI bisnis | D15: 10000000 | E15: 45656 | F15: 45659
A16: deposit | B16: Joko wardoyo | C16: BRI bisnis | D16: 40000000 | E16: 45656 | F16: 45659
A17: deposit | B17: Mb linda | C17: BRI bisnis | D17: 50000 | E17: 45657 | F17: 45659
A18: hiu 9000x8200 | B18: Bu yatini ngawi | C18: BCA cv surya | D18: 73800000 | E18: 45658 | F18: 45661
A19: hiu 9000x8500 | B19: Kopti giri | C19: BRI bisnis | D19: 76500000 | E19: 45660 | F19: 45663
A20: ongkir | B20: Pak anwar | C20: BCA cv surya | D20: 1000000 | E20: 45660 | F20: 45661
A21: minyak 185000x800 + ongkir | B21: Mas nanang bjn | C21: BCA individu | D21: 149200000 | E21: 45660 | F21: 45661
... A27: lotus 9000x8300 | B27: Kopti giri | C27: BRI bisnis | D27: 44500000 | E27: 45663 | F27: 45671
D28: 30200000 | E28: 45664 | F28: 45671
A29: ongkir | B29: Abah slamet | C29: BCA cv putra | D29: 2430000 | E29: 45663 | F29: 45664
A30: bagi hasil | B30: Pak iwan | C30: BCA individu | D30: 450000 | E30: 45663 | F30: 45664
A31: panah 8500x8550 | B31: Bu yatini ngawi | C31: BRI bisnis | D31: 72675000 | E31: 45665 | F31: 45666
A32: ongkir | B32: Pak anwar | C32: BCA cv surya | D32: 650000 | E32: 45666 | F32: 45667 | G32: kurang 450rb
A33: tulip 9000x8650 | B33: Abah slamet | C33: BRI bisnis | D33: 77850000 | E33: 45667 | F33: 45673
A34: minyak 185000x800 + ongkir | B34: Mas nanang bjn | C34: BCA individu | D34: 149200000 | E34: 45668 | F34: 45670
A35: sip 9000x8500 | B35: Kopti giri | C35: BRI bisnis | D35: 60000000 | E35: 45668 | F35: 45698
D36: 16500000 | E36: 45670
A37: panah 8500x8600 | B37: Bu yatini ngawi | C37: BRI bisnis | D37: 73100000 | E37: 45671 | F37: 45672
A38: hiu 9000x8550 | B38: Bu yatini ngawi | C38: BCA cv surya | D38: 76950000 | E38: 45671 | F38: 45673
A39: deposit | B39: Bu tutik | C39: BCA cv putra | D39: 2710000 | E39: 45672 | F39: 45677
A40: ongkir | B40: Pak ramin | C40: BCA individu | D40: 1600000 | E40: 45672 | F40: 45674
A41: ongkir | B41: Abah slamet | C41: BRI bisnis | D41: 1215000 | E41: 45667 | F41: 45674
A42: tulip 9000x8300 | B42: Bu iin | C42: BCA cv putra | D42: 74700000 | E42: 45672 | F42: 45682
A43: lotus 9000x8300 | B43: Bu iin | C43: BCA cv putra | D43: 74700000 | E43: 45672 | F43: 45674
A44: tomat/BW 9000x8450 | B44: Kopti giri | C44: BRI bisnis | D44: 39000000 | E44: 45672 | F44: 45688
D45: 37050000 | E45: 45673
A46: sip 9000x8650 | B46: Abah slamet | C46: BCA cv putra | D46: 77850000 | E46: 45673 | F46: 45674
...

Sheet Audit mingguan
A1: CV PUTRA BUMI BERKAH
A2: PERHITUNGAN KEUANGAN
A3: 45549
E5: Rincian pinjaman BRI =
C6: Saldo
A7: Aset | C7: IDR | E7: Pelunasan agrico tgl 31/5 | F7: 2000000000
E8: Pelunasan pinjaman bu tutik oktober | F8: 500000000
B9: Saldo bank | C9: 1.7547283e+09 | E9: Deposit saldo | F9: 335000000
B10: Aset bergerak | C10: 1992000000 | E10: Biaya notaris + pencairan BRI | F10: 83000000
B11: Piutang toko | C11: 490025000 | F11: =SUM(F7:F10) -> 2918000000
B12: Piutang all customer + ragi | C12: 1962203500
B13: Stock ragi 110karton | C13: 66275000 | E13: Rincian akhir pinjaman BRI =
B14: Pak nanok + pak ozi | C14: 55000000 | E14: Pemasukan
C15: =SUM(C9:C14) -> 6.3202318e+09 | E15: Sisa modal dari BRI | F15: 1.6105943e+09
E16: Laba jan-agust | F16: 793614325
A17: Hutang | F17: =SUM(F15:F16) -> 2.4042086e+09
B18: PT Agrico International | C18: 2341775000 | E18: Pengeluaran
B19: PT JPM-ADM Indonesia | C19: 1223062500 | E19: Juni - sept 14/9 | F19: 1770286500
B20: PT Terus Makmur Mandiri | C20: 144800000 | F20: =F19 -> 1770286500
B21: Bu tutik | C21: 500000000
B22: Mb retno | C22: 500000000 | E22: Pemasukan - pengeluaran | F22: =F17-F20 -> 6.3392211e+08
C23: =SUM(C18:C22) -> 4709637500
A25: Total aset + Piutang - Hutang | C25: =C15-C23 -> 1.6105943e+09
